Workbook

Sheet Global_Players
A1: Player_ID | B1: Leaderboard_Rank | C1: Deployments | D1: Vehicle_Time_Hour | E1: Mixed_Time_Hour | F1: Infantry_Time_Hour | G1: Battle_Royale_Hour | H1: Map_Tendency | I1: Assault_Time_Hour | J1: Engineer_Time_Hour | K1: Recon_Time_Hour | L1: Support_Time_Hour | M1: Total_Time_Hour | N1: Primary_Class | O1: Dominant-Class | P1: Dominance Percentage | Q1: Snapshot_Date
A2: Stann83cz | B2: {=_xlfn.SEQUENCE(1000,1,7,10)} -> 7 | C2: 42845 | D2: =SUM(Global_Player_Modes!C2:D2) -> 224 | E2: =SUM(Global_Player_Modes!E2:F2) -> 105.5 | F2: =SUM(Global_Player_Modes!G2:M2) -> 325.5 | G2: =SUM(Global_Player_Modes!N2:O2) -> 11 | H2: =IF(SUM(D2:G2)=0,"",IF(G2/SUM(D2:G2)>=0.5,"Battle Royale",IF(F2/SUM(D2:F2)>=0.6,"Infantry-Heavy",IF((D2+0.7*E2)/SUM(D2:F2)>=0.65,"Vehicle-Heavy","Mixed")))) -> Mixed | I2: 290 | J2: 42 | K2: 150 | L2: 65 | M2: =SUM(I2:L2) -> 547 | N2: {=_xlfn.LET(_xlpm.total,SUM(I2:L2),_xlpm.maxv,MAX(I2:L2),IF(_xlpm.total=0,"",IF(_xlpm.maxv/_xlpm.total<0.45,"Mixed-Class",_xlfn.IFS(_xlpm.maxv=I2,"Assault",_xlpm.maxv=J2,"Engineer",_xlpm.maxv=K2,"Recon",_xlpm.maxv=L2,"Support"))))} -> Assault | O2: =_xlfn.LET(_xlpm.total,SUM(I2:L2),IF(_xlpm.total=0,"",MAX(I2:L2)/_xlpm.total>=0.45)) -> TRUE | P2: =_xlfn.LET(_xlpm.total,SUM(I2:L2),IF(_xlpm.total=0,"",MAX(I2:L2)/_xlpm.total)) -> 0.53016453 | Q2: 46046
A3: Sir Jekyll | B3: 17 | C3: 38077 | D3: =SUM(Global_Player_Modes!C3:D3) -> 349 | E3: =SUM(Global_Player_Modes!E3:F3) -> 106.5 | F3: =SUM(Global_Player_Modes!G3:M3) -> 101.5 | G3: =SUM(Global_Player_Modes!N3:O3) -> 124 | H3: =IF(SUM(D3:G3)=0,"",IF(G3/SUM(D3:G3)>=0.5,"Battle Royale",IF(F3/SUM(D3:F3)>=0.6,"Infantry-Heavy",IF((D3+0.7*E3)/SUM(D3:F3)>=0.65,"Vehicle-Heavy","Mixed")))) -> Vehicle-Heavy | I3: 176 | J3: 216 | K3: 66 | L3: 130 | M3: =SUM(I3:L3) -> 588 | N3: {=_xlfn.LET(_xlpm.total,SUM(I3:L3),_xlpm.maxv,MAX(I3:L3),IF(_xlpm.total=0,"",IF(_xlpm.maxv/_xlpm.total<0.45,"Mixed-Class",_xlfn.IFS(_xlpm.maxv=I3,"Assault",_xlpm.maxv=J3,"Engineer",_xlpm.maxv=K3,"Recon",_xlpm.maxv=L3,"Support"))))} -> Mixed-Class | O3: =_xlfn.LET(_xlpm.total,SUM(I3:L3),IF(_xlpm.total=0,"",MAX(I3:L3)/_xlpm.total>=0.45)) -> FALSE | P3: =_xlfn.LET(_xlpm.total,SUM(I3:L3),IF(_xlpm.total=0,"",MAX(I3:L3)/_xlpm.total)) -> 0.36734694 | Q3: 46046
A4: elkikisk | B4: 27 | C4: 36961 | D4: =SUM(Global_Player_Modes!C4:D4) -> 801 | E4: =SUM(Global_Player_Modes!E4:F4) -> 122 | F4: =SUM(Global_Player_Modes!G4:M4) -> 14 | G4: =SUM(Global_Player_Modes!N4:O4) -> 0.35 | H4: =IF(SUM(D4:G4)=0,"",IF(G4/SUM(D4:G4)>=0.5,"Battle Royale",IF(F4/SUM(D4:F4)>=0.6,"Infantry-Heavy",IF((D4+0.7*E4)/SUM(D4:F4)>=0.65,"Vehicle-Heavy","Mixed")))) -> Vehicle-Heavy | I4: 326 | J4: 196 | K4: 41 | L4: 223 | M4: =SUM(I4:L4) -> 786 | N4: {=_xlfn.LET(_xlpm.total,SUM(I4:L4),_xlpm.maxv,MAX(I4:L4),IF(_xlpm.total=0,"",IF(_xlpm.maxv/_xlpm.total<0.45,"Mixed-Class",_xlfn.IFS(_xlpm.maxv=I4,"Assault",_xlpm.maxv=J4,"Engineer",_xlpm.maxv=K4,"Recon",_xlpm.maxv=L4,"Support"))))} -> Mixed-Class | O4: =_xlfn.LET(_xlpm.total,SUM(I4:L4),IF(_xlpm.total=0,"",MAX(I4:L4)/_xlpm.total>=0.45)) -> FALSE | P4: =_xlfn.LET(_xlpm.total,SUM(I4:L4),IF(_xlpm.total=0,"",MAX(I4:L4)/_xlpm.total)) -> 0.41475827 | Q4: 46048
A5: HSBxEWIKKED | B5: 37 | C5: 35380 | D5: =SUM(Global_Player_Modes!C5:D5) -> 100.25 | E5: =SUM(Global_Player_Modes!E5:F5) -> 93 | F5: =SUM(Global_Player_Modes!G5:M5) -> 601 | G5: =SUM(Global_Player_Modes!N5:O5) -> 115 | H5: =IF(SUM(D5:G5)=0,"",IF(G5/SUM(D5:G5)>=0.5,"Battle Royale",IF(F5/SUM(D5:F5)>=0.6,"Infantry-Heavy",IF((D5+0.7*E5)/SUM(D5:F5)>=0.65,"Vehicle-Heavy","Mixed")))) -> Infantry-Heavy | I5: 1 | J5: 8 | K5: 105 | L5: 671 | M5: =SUM(I5:L5) -> 785 | N5: {=_xlfn.LET(_xlpm.total,SUM(I5:L5),_xlpm.maxv,MAX(I5:L5),IF(_xlpm.total=0,"",IF(_xlpm.maxv/_xlpm.total<0.5,"Mixed-Class",_xlfn.IFS(_xlpm.maxv=I5,"Assault",_xlpm.maxv=J5,"Engineer",_xlpm.maxv=K5,"Recon",_xlpm.maxv=L5,"Support"))))} -> Support | O5: =_xlfn.LET(_xlpm.total,SUM(I5:L5),IF(_xlpm.total=0,"",MAX(I5:L5)/_xlpm.total>=0.5)) -> TRUE | P5: =_xlfn.LET(_xlpm.total,SUM(I5:L5),IF(_xlpm.total=0,"",MAX(I5:L5)/_xlpm.total)) -> 0.85477707 | Q5: 46048
A6: TheBishopDeath | B6: 47 | C6: 34290 | D6: =SUM(Global_Player_Modes!C6:D6) -> 549.5 | E6: =SUM(Global_Player_Modes!E6:F6) -> 83.75 | F6: =SUM(Global_Player_Modes!G6:M6) -> 42 | G6: =SUM(Global_Player_Modes!N6:O6) -> 3.75 | H6: =IF(SUM(D6:G6)=0,"",IF(G6/SUM(D6:G6)>=0.5,"Battle Royale",IF(F6/SUM(D6:F6)>=0.6,"Infantry-Heavy",IF((D6+0.7*E6)/SUM(D6:F6)>=0.65,"Vehicle-Heavy","Mixed")))) -> Vehicle-Heavy | I6: 105 | J6: 390 | K6: 3 | L6: 37 | M6: =SUM(I6:L6) -> 535 | N6: {=_xlfn.LET(_xlpm.total,SUM(I6:L6),_xlpm.maxv,MAX(I6:L6),IF(_xlpm.total=0,"",IF(_xlpm.maxv/_xlpm.total<0.5,"Mixed-Class",_xlfn.IFS(_xlpm.maxv=I6,"Assault",_xlpm.maxv=J6,"Engineer",_xlpm.maxv=K6,"Recon",_xlpm.maxv=L6,"Support"))))} -> Engineer | O6: =_xlfn.LET(_xlpm.total,SUM(I6:L6),IF(_xlpm.total=0,"",MAX(I6:L6)/_xlpm.total>=0.5)) -> TRUE | P6: =_xlfn.LET(_xlpm.total,SUM(I6:L6),IF(_xlpm.total=0,"",MAX(I6:L6)/_xlpm.total)) -> 0.72897196 | Q6: 46048
A7: AncientWizardGuy | B7: 57 | C7: 33277 | D7: =SUM(Global_Player_Modes!C7:D7) -> 476 | E7: =SUM(Global_Player_Modes!E7:F7) -> 250 | F7: =SUM(Global_Player_Modes!G7:M7) -> 2 | G7: =SUM(Global_Player_Modes!N7:O7) -> 0 | H7: =IF(SUM(D7:G7)=0,"",IF(G7/SUM(D7:G7)>=0.5,"Battle Royale",IF(F7/SUM(D7:F7)>=0.6,"Infantry-Heavy",IF((D7+0.7*E7)/SUM(D7:F7)>=0.65,"Vehicle-Heavy","Mixed")))) -> Vehicle-Heavy | I7: 104 | J7: 156 | K7: 126 | L7: 211 | M7: =SUM(I7:L7) -> 597 | N7: {=_xlfn.LET(_xlpm.total,SUM(I7:L7),_xlpm.maxv,MAX(I7:L7),IF(_xlpm.total=0,"",IF(_xlpm.maxv/_xlpm.total<0.5,"Mixed-Class",_xlfn.IFS(_xlpm.maxv=I7,"Assault",_xlpm.maxv=J7,"Engineer",_xlpm.maxv=K7,"Recon",_xlpm.maxv=L7,"Support"))))} -> Mixed-Class | O7: =_xlfn.LET(_xlpm.total,SUM(I7:L7),IF(_xlpm.total=0,"",MAX(I7:L7)/_xlpm.total>=0.5)) -> FALSE | P7: =_xlfn.LET(_xlpm.total,SUM(I7:L7),IF(_xlpm.total=0,"",MAX(I7:L7)/_xlpm.total)) -> 0.35343384 | Q7: 46048
A8: M5_eaglez | B8: 67 | C8: 32631 | D8: =SUM(Global_Player_Modes!C8:D8) -> 214 | E8: =SUM(Global_Player_Modes!E8:F8) -> 453.5 | F8: =SUM(Global_Player_Modes!G8:M8) -> 0.25 | G8: =SUM(Global_Player_Modes!N8:O8) -> 0 | H8: =IF(SUM(D8:G8)=0,"",IF(G8/SUM(D8:G8)>=0.5,"Battle Royale",IF(F8/SUM(D8:F8)>=0.6,"Infantry-Heavy",IF((D8+0.7*E8)/SUM(D8:F8)>=0.65,"Vehicle-Heavy","Mixed")))) -> Vehicle-Heavy | I8: 233 | J8: 68 | K8: 62 | L8: 85 | M8: =SUM(I8:L8) -> 448 | N8: {=_xlfn.LET(_xlpm.total,SUM(I8:L8),_xlpm.maxv,MAX(I8:L8),IF(_xlpm.total=0,"",IF(_xlpm.maxv/_xlpm.total<0.5,"Mixed-Class",_xlfn.IFS(_xlpm.maxv=I8,"Assault",_xlpm.maxv=J8,"Engineer",_xlpm.maxv=K8,"Recon",_xlpm.maxv=L8,"Support"))))} -> Assault | O8: =_xlfn.LET(_xlpm.total,SUM(I8:L8),IF(_xlpm.total=0,"",MAX(I8:L8)/_xlpm.total>=0.5)) -> TRUE | P8: =_xlfn.LET(_xlpm.total,SUM(I8:L8),IF(_xlpm.total=0,"",MAX(I8:L8)/_xlpm.total)) -> 0.52008929 | Q8: 46048
A9: Ragefast2311 | B9: 77 | C9: 32224 | D9: =SUM(Global_Player_Modes!C9:D9) -> 43 | E9: =SUM(Global_Player_Modes!E9:F9) -> 49.5 | F9: =SUM(Global_Player_Modes!G9:M9) -> 363.75 | G9: =SUM(Global_Player_Modes!N9:O9) -> 15.25 | H9: =IF(SUM(D9:G9)=0,"",IF(G9/SUM(D9:G9)>=0.5,"Battle Royale",IF(F9/SUM(D9:F9)>=0.6,"Infantry-Heavy",IF((D9+0.7*E9)/SUM(D9:F9)>=0.65,"Vehicle-Heavy","Mixed")))) -> Infantry-Heavy | I9: 10 | J9: 9 | K9: 12 | L9: 409 | M9: =SUM(I9:L9) -> 440 | N9: {=_xlfn.LET(_xlpm.total,SUM(I9:L9),_xlpm.maxv,MAX(I9:L9),IF(_xlpm.total=0,"",IF(_xlpm.maxv/_xlpm.total<0.5,"Mixed-Class",_xlfn.IFS(_xlpm.maxv=I9,"Assault",_xlpm.maxv=J9,"Engineer",_xlpm.maxv=K9,"Recon",_xlpm.maxv=L9,"Support"))))} -> Support | O9: =_xlfn.LET(_xlpm.total,SUM(I9:L9),IF(_xlpm.total=0,"",MAX(I9:L9)/_xlpm.total>=0.5)) -> TRUE | P9: =_xlfn.LET(_xlpm.total,SUM(I9:L9),IF(_xlpm.total=0,"",MAX(I9:L9)/_xlpm.total)) -> 0.92954545 | Q9: 46048
A10: xCPC464x | B10: 87 | C10: 31404 | D10: =SUM(Global_Player_Modes!C10:D10) -> 472 | E10: =SUM(Global_Player_Modes!E10:F10) -> 171 | F10: =SUM(Global_Player_Modes!G10:M10) -> 217 | G10: =SUM(Global_Player_Modes!N10:O10) -> 128 | H10: =IF(SUM(D10:G10)=0,"",IF(G10/SUM(D10:G10)>=0.5,"Battle Royale",IF(F10/SUM(D10:F10)>=0.6,"Infantry-Heavy",IF((D10+0.7*E10)/SUM(D10:F10)>=0.65,"Vehicle-Heavy","Mixed")))) -> Vehicle-Heavy | I10: 360 | J10: 35 | K10: 204 | L10: 56 | M10: =SUM(I10:L10) -> 655 | N10: {=_xlfn.LET(_xlpm.total,SUM(I10:L10),_xlpm.maxv,MAX(I10:L10),IF(_xlpm.total=0,"",IF(_xlpm.maxv/_xlpm.total<0.5,"Mixed-Class",_xlfn.IFS(_xlpm.maxv=I10,"Assault",_xlpm.maxv=J10,"Engineer",_xlpm.maxv=K10,"Recon",_xlpm.maxv=L10,"Support"))))} -> Assault | O10: =_xlfn.LET(_xlpm.total,SUM(I10:L10),IF(_xlpm.total=0,"",MAX(I10:L10)/_xlpm.total>=0.5)) -> TRUE | P10: =_xlfn.LET(_xlpm.total,SUM(I10:L10),IF(_xlpm.total=0,"",MAX(I10:L10)/_xlpm.total)) -> 0.54961832 | Q10: 46048
A11: Benzo_ | B11: 97 | C11: 30772 | D11: =SUM(Global_Player_Modes!C11:D11) -> 78 | E11: =SUM(Global_Player_Modes!E11:F11) -> 635.25 | F11: =SUM(Global_Player_Modes!G11:M11) -> 11.5 | G11: =SUM(Global_Player_Modes!N11:O11) -> 20.25 | H11: =IF(SUM(D11:G11)=0,"",IF(G11/SUM(D11:G11)>=0.5,"Battle Royale",IF(F11/SUM(D11:F11)>=0.6,"Infantry-Heavy",IF((D11+0.7*E11)/SUM(D11:F11)>=0.65,"Vehicle-Heavy","Mixed")))) -> Vehicle-Heavy | I11: 27 | J11: 152 | K11: 140 | L11: 203 | M11: =SUM(I11:L11) -> 522 | N11: {=_xlfn.LET(_xlpm.total,SUM(I11:L11),_xlpm.maxv,MAX(I11:L11),IF(_xlpm.total=0,"",IF(_xlpm.maxv/_xlpm.total<0.5,"Mixed-Class",_xlfn.IFS(_xlpm.maxv=I11,"Assault",_xlpm.maxv=J11,"Engineer",_xlpm.maxv=K11,"Recon",_xlpm.maxv=L11,"Support"))))} -> Mixed-Class | O11: =_xlfn.LET(_xlpm.total,SUM(I11:L11),IF(_xlpm.total=0,"",MAX(I11:L11)/_xlpm.total>=0.5)) -> FALSE | P11: =_xlfn.LET(_xlpm.total,SUM(I11:L11),IF(_xlpm.total=0,"",MAX(I11:L11)/_xlpm.total)) -> 0.38888889 | Q11: 46048
A12: rgayregger | B12: 107 | C12: 31795 | H12: =IF(SUM(D12:G12)=0,"",IF(G12/SUM(D12:G12)>=0.5,"Battle Royale",IF(F12/SUM(D12:F12)>=0.6,"Infantry-Heavy",IF((D12+0.7*E12)/SUM(D12:F12)>=0.7,"Vehicle-Heavy","Mixed")))) | I12: 252 | J12: 59 | K12: 30 | L12: 22 | M12: =SUM(I12:L12) -> 363 | N12: {=_xlfn.LET(_xlpm.total,SUM(I12:L12),_xlpm.maxv,MAX(I12:L12),IF(_xlpm.total=0,"",IF(_xlpm.maxv/_xlpm.total<0.5,"Mixed-Class",_xlfn.IFS(_xlpm.maxv=I12,"Assault",_xlpm.maxv=J12,"Engineer",_xlpm.maxv=K12,"Recon",_xlpm.maxv=L12,"Support"))))} -> Assault | O12: =_xlfn.LET(_xlpm.total,SUM(I12:L12),IF(_xlpm.total=0,"",MAX(I12:L12)/_xlpm.total>=0.5)) -> TRUE | P12: =_xlfn.LET(_xlpm.total,SUM(I12:L12),IF(_xlpm.total=0,"",MAX(I12:L12)/_xlpm.total)) -> 0.69421488 | Q12: 46056
B13: 117 | H13: =IF(SUM(D13:G13)=0,"",IF(G13/SUM(D13:G13)>=0.5,"Battle Royale",IF(F13/SUM(D13:F13)>=0.6,"Infantry-Heavy",IF((D13+0.7*E13)/SUM(D13:F13)>=0.7,"Vehicle-Heavy","Mixed")))) | M13: =SUM(I13:L13) -> 0 | N13: {=_xlfn.LET(_xlpm.total,SUM(I13:L13),_xlpm.maxv,MAX(I13:L13),IF(_xlpm.total=0,"",IF(_xlpm.maxv/_xlpm.total<0.5,"Mixed-Class",_xlfn.IFS(_xlpm.maxv=I13,"Assault",_xlpm.maxv=J13,"Engineer",_xlpm.maxv=K13,"Recon",_xlpm.maxv=L13,"Support"))))} | O13: =_xlfn.LET(_xlpm.total,SUM(I13:L13),IF(_xlpm.total=0,"",MAX(I13:L13)/_xlpm.total>=0.5)) | P13: =_xlfn.LET(_xlpm.total,SUM(I13:L13),IF(_xlpm.total=0,"",MAX(I13:L13)/_xlpm.total))
B14: 127 | H14: =IF(SUM(D14:G14)=0,"",IF(G14/SUM(D14:G14)>=0.5,"Battle Royale",IF(F14/SUM(D14:F14)>=0.6,"Infantry-Heavy",IF((D14+0.7*E14)/SUM(D14:F14)>=0.7,"Vehicle-Heavy","Mixed")))) | M14: =SUM(I14:L14) -> 0 | N14: {=_xlfn.LET(_xlpm.total,SUM(I14:L14),_xlpm.maxv,MAX(I14:L14),IF(_xlpm.total=0,"",IF(_xlpm.maxv/_xlpm.total<0.5,"Mixed-Class",_xlfn.IFS(_xlpm.maxv=I14,"Assault",_xlpm.maxv=J14,"Engineer",_xlpm.maxv=K14,"Recon",_xlpm.maxv=L14,"Support"))))} | O14: =_xlfn.LET(_xlpm.total,SUM(I14:L14),IF(_xlpm.total=0,"",MAX(I14:L14)/_xlpm.total>=0.5)) | P14: =_xlfn.LET(_xlpm.total,SUM(I14:L14),IF(_xlpm.total=0,"",MAX(I14:L14)/_xlpm.total))
B15: 137 | H15: =IF(SUM(D15:G15)=0,"",IF(G15/SUM(D15:G15)>=0.5,"Battle Royale",IF(F15/SUM(D15:F15)>=0.6,"Infantry-Heavy",IF((D15+0.7*E15)/SUM(D15:F15)>=0.7,"Vehicle-Heavy","Mixed")))) | M15: =SUM(I15:L15) -> 0 | N15: {=_xlfn.LET(_xlpm.total,SUM(I15:L15),_xlpm.maxv,MAX(I15:L15),IF(_xlpm.total=0,"",IF(_xlpm.maxv/_xlpm.total<0.5,"Mixed-Class",_xlfn.IFS(_xlpm.maxv=I15,"Assault",_xlpm.maxv=J15,"Engineer",_xlpm.maxv=K15,"Recon",_xlpm.maxv=L15,"Support"))))} | O15: =_xlfn.LET(_xlpm.total,SUM(I15:L15),IF(_xlpm.total=0,"",MAX(I15:L15)/_xlpm.total>=0.5)) | P15: =_xlfn.LET(_xlpm.total,SUM(I15:L15),IF(_xlpm.total=0,"",MAX(I15:L15)/_xlpm.total))
B16: 147 | H16: =IF(SUM(D16:G16)=0,"",IF(G16/SUM(D16:G16)>=0.5,"Battle Royale",IF(F16/SUM(D16:F16)>=0.6,"Infantry-Heavy",IF((D16+0.7*E16)/SUM(D16:F16)>=0.7,"Vehicle-Heavy","Mixed")))) | M16: =SUM(I16:L16) -> 0 | N16: {=_xlfn.LET(_xlpm.total,SUM(I16:L16),_xlpm.maxv,MAX(I16:L16),IF(_xlpm.total=0,"",IF(_xlpm.maxv/_xlpm.total<0.5,"Mixed-Class",_xlfn.IFS(_xlpm.maxv=I16,"Assault",_xlpm.maxv=J16,"Engineer",_xlpm.maxv=K16,"Recon",_xlpm.maxv=L16,"Support"))))} | O16: =_xlfn.LET(_xlpm.total,SUM(I16:L16),IF(_xlpm.total=0,"",MAX(I16:L16)/_xlpm.total>=0.5)) | P16: =_xlfn.LET(_xlpm.total,SUM(I16:L16),IF(_xlpm.total=0,"",MAX(I16:L16)/_xlpm.total))
B17: 157 | H17: =IF(SUM(D17:G17)=0,"",IF(G17/SUM(D17:G17)>=0.5,"Battle Royale",IF(F17/SUM(D17:F17)>=0.6,"Infantry-Heavy",IF((D17+0.7*E17)/SUM(D17:F17)>=0.7,"Vehicle-Heavy","Mixed")))) | M17: =SUM(I17:L17) -> 0 | N17: {=_xlfn.LET(_xlpm.total,SUM(I17:L17),_xlpm.maxv,MAX(I17:L17),IF(_xlpm.total=0,"",IF(_xlpm.maxv/_xlpm.total<0.5,"Mixed-Class",_xlfn.IFS(_xlpm.maxv=I17,"Assault",_xlpm.maxv=J17,"Engineer",_xlpm.maxv=K17,"Recon",_xlpm.maxv=L17,"Support"))))} | O17: =_xlfn.LET(_xlpm.total,SUM(I17:L17),IF(_xlpm.total=0,"",MAX(I17:L17)/_xlpm.total>=0.5)) | P17: =_xlfn.LET(_xlpm.total,SUM(I17:L17),IF(_xlpm.total=0,"",MAX(I17:L17)/_xlpm.total))
B18: 167 | H18: =IF(SUM(D18:G18)=0,"",IF(G18/SUM(D18:G18)>=0.5,"Battle Royale",IF(F18/SUM(D18:F18)>=0.6,"Infantry-Heavy",IF((D18+0.7*E18)/SUM(D18:F18)>=0.7,"Vehicle-Heavy","Mixed")))) | M18: =SUM(I18:L18) -> 0 | N18: {=_xlfn.LET(_xlpm.total,SUM(I18:L18),_xlpm.maxv,MAX(I18:L18),IF(_xlpm.total=0,"",IF(_xlpm.maxv/_xlpm.total<0.5,"Mixed-Class",_xlfn.IFS(_xlpm.maxv=I18,"Assault",_xlpm.maxv=J18,"Engineer",_xlpm.maxv=K18,"Recon",_xlpm.maxv=L18,"Support"))))} | O18: =_xlfn.LET(_xlpm.total,SUM(I18:L18),IF(_xlpm.total=0,"",MAX(I18:L18)/_xlpm.total>=0.5)) | P18: =_xlfn.LET(_xlpm.total,SUM(I18:L18),IF(_xlpm.total=0,"",MAX(I18:L18)/_xlpm.total))
B19: 177 | H19: =IF(SUM(D19:G19)=0,"",IF(G19/SUM(D19:G19)>=0.5,"Battle Royale",IF(F19/SUM(D19:F19)>=0.6,"Infantry-Heavy",IF((D19+0.7*E19)/SUM(D19:F19)>=0.7,"Vehicle-Heavy","Mixed")))) | M19: =SUM(I19:L19) -> 0 | N19: {=_xlfn.LET(_xlpm.total,SUM(I19:L19),_xlpm.maxv,MAX(I19:L19),IF(_xlpm.total=0,"",IF(_xlpm.maxv/_xlpm.total<0.5,"Mixed-Class",_xlfn.IFS(_xlpm.maxv=I19,"Assault",_xlpm.maxv=J19,"Engineer",_xlpm.maxv=K19,"Recon",_xlpm.maxv=L19,"Support"))))} | O19: =_xlfn.LET(_xlpm.total,SUM(I19:L19),IF(_xlpm.total=0,"",MAX(I19:L19)/_xlpm.total>=0.5)) | P19: =_xlfn.LET(_xlpm.total,SUM(I19:L19),IF(_xlpm.total=0,"",MAX(I19:L19)/_xlpm.total))
B20: 187 | H20: =IF(SUM(D20:G20)=0,"",IF(G20/SUM(D20:G20)>=0.5,"Battle Royale",IF(F20/SUM(D20:F20)>=0.6,"Infantry-Heavy",IF((D20+0.7*E20)/SUM(D20:F20)>=0.7,"Vehicle-Heavy","Mixed")))) | M20: =SUM(I20:L20) -> 0 | N20: {=_xlfn.LET(_xlpm.total,SUM(I20:L20),_xlpm.maxv,MAX(I20:L20),IF(_xlpm.total=0,"",IF(_xlpm.maxv/_xlpm.total<0.5,"Mixed-Class",_xlfn.IFS(_xlpm.maxv=I20,"Assault",_xlpm.maxv=J20,"Engineer",_xlpm.maxv=K20,"Recon",_xlpm.maxv=L20,"Support"))))} | O20: =_xlfn.LET(_xlpm.total,SUM(I20:L20),IF(_xlpm.total=0,"",MAX(I20:L20)/_xlpm.total>=0.5)) | P20: =_xlfn.LET(_xlpm.total,SUM(I20:L20),IF(_xlpm.total=0,"",MAX(I20:L20)/_xlpm.total))
B21: 197 | H21: =IF(SUM(D21:G21)=0,"",IF(G21/SUM(D21:G21)>=0.5,"Battle Royale",IF(F21/SUM(D21:F21)>=0.6,"Infantry-Heavy",IF((D21+0.7*E21)/SUM(D21:F21)>=0.7,"Vehicle-Heavy","Mixed")))) | M21: =SUM(I21:L21) -> 0 | N21: {=_xlfn.LET(_xlpm.total,SUM(I21:L21),_xlpm.maxv,MAX(I21:L21),IF(_xlpm.total=0,"",IF(_xlpm.maxv/_xlpm.total<0.5,"Mixed-Class",_xlfn.IFS(_xlpm.maxv=I21,"Assault",_xlpm.maxv=J21,"Engineer",_xlpm.maxv=K21,"Recon",_xlpm.maxv=L21,"Support"))))} | O21: =_xlfn.LET(_xlpm.total,SUM(I21:L21),IF(_xlpm.total=0,"",MAX(I21:L21)/_xlpm.total>=0.5)) | P21: =_xlfn.LET(_xlpm.total,SUM(I21:L21),IF(_xlpm.total=0,"",MAX(I21:L21)/_xlpm.total))
B22: 207 | H22: =IF(SUM(D22:G22)=0,"",IF(G22/SUM(D22:G22)>=0.5,"Battle Royale",IF(F22/SUM(D22:F22)>=0.6,"Infantry-Heavy",IF((D22+0.7*E22)/SUM(D22:F22)>=0.7,"Vehicle-Heavy","Mixed")))) | M22: =SUM(I22:L22) -> 0 | N22: {=_xlfn.LET(_xlpm.total,SUM(I22:L22),_xlpm.maxv,MAX(I22:L22),IF(_xlpm.total=0,"",IF(_xlpm.maxv/_xlpm.total<0.5,"Mixed-Class",_xlfn.IFS(_xlpm.maxv=I22,"Assault",_xlpm.maxv=J22,"Engineer",_xlpm.maxv=K22,"Recon",_xlpm.maxv=L22,"Support"))))} | O22: =_xlfn.LET(_xlpm.total,SUM(I22:L22),IF(_xlpm.total=0,"",MAX(I22:L22)/_xlpm.total>=0.5)) | P22: =_xlfn.LET(_xlpm.total,SUM(I22:L22),IF(_xlpm.total=0,"",MAX(I22:L22)/_xlpm.total))
B23: 217 | H23: =IF(SUM(D23:G23)=0,"",IF(G23/SUM(D23:G23)>=0.5,"Battle Royale",IF(F23/SUM(D23:F23)>=0.6,"Infantry-Heavy",IF((D23+0.7*E23)/SUM(D23:F23)>=0.7,"Vehicle-Heavy","Mixed")))) | M23: =SUM(I23:L23) -> 0 | N23: {=_xlfn.LET(_xlpm.total,SUM(I23:L23),_xlpm.maxv,MAX(I23:L23),IF(_xlpm.total=0,"",IF(_xlpm.maxv/_xlpm.total<0.5,"Mixed-Class",_xlfn.IFS(_xlpm.maxv=I23,"Assault",_xlpm.maxv=J23,"Engineer",_xlpm.maxv=K23,"Recon",_xlpm.maxv=L23,"Support"))))} | O23: =_xlfn.LET(_xlpm.total,SUM(I23:L23),IF(_xlpm.total=0,"",MAX(I23:L23)/_xlpm.total>=0.5)) | P23: =_xlfn.LET(_xlpm.total,SUM(I23:L23),IF(_xlpm.total=0,"",MAX(I23:L23)/_xlpm.total))
B24: 227 | H24: =IF(SUM(D24:G24)=0,"",IF(G24/SUM(D24:G24)>=0.5,"Battle Royale",IF(F24/SUM(D24:F24)>=0.6,"Infantry-Heavy",IF((D24+0.7*E24)/SUM(D24:F24)>=0.7,"Vehicle-Heavy","Mixed")))) | M24: =SUM(I24:L24) -> 0 | N24: {=_xlfn.LET(_xlpm.total,SUM(I24:L24),_xlpm.maxv,MAX(I24:L24),IF(_xlpm.total=0,"",IF(_xlpm.maxv/_xlpm.total<0.5,"Mixed-Class",_xlfn.IFS(_xlpm.maxv=I24,"Assault",_xlpm.maxv=J24,"Engineer",_xlpm.maxv=K24,"Recon",_xlpm.maxv=L24,"Support"))))} | O24: =_xlfn.LET(_xlpm.total,SUM(I24:L24),IF(_xlpm.total=0,"",MAX(I24:L24)/_xlpm.total>=0.5)) | P24: =_xlfn.LET(_xlpm.total,SUM(I24:L24),IF(_xlpm.total=0,"",MAX(I24:L24)/_xlpm.total))
... B1000: 9987 | H1000: =IF(SUM(D1000:G1000)=0,"",IF(G1000/SUM(D1000:G1000)>=0.5,"Battle Royale",IF(F1000/SUM(D1000:F1000)>=0.6,"Infantry-Heavy",IF((D1000+0.7*E1000)/SUM(D1000:F1000)>=0.7,"Vehicle-Heavy","Mixed")))) | M1000: =SUM(I1000:L1000) -> 0 | N1000: {=_xlfn.LET(_xlpm.total,SUM(I1000:L1000),_xlpm.maxv,MAX(I1000:L1000),IF(_xlpm.total=0,"",IF(_xlpm.maxv/_xlpm.total<0.5,"Mixed-Class",_xlfn.IFS(_xlpm.maxv=I1000,"Assault",_xlpm.maxv=J1000,"Engineer",_xlpm.maxv=K1000,"Recon",_xlpm.maxv=L1000,"Support"))))} | O1000: =_xlfn.LET(_xlpm.total,SUM(I1000:L1000),IF(_xlpm.total=0,"",MAX(I1000:L1000)/_xlpm.total>=0.5)) | P1000: =_xlfn.LET(_xlpm.total,SUM(I1000:L1000),IF(_xlpm.total=0,"",MAX(I1000:L1000)/_xlpm.total))
B1001: 9997 | M1001: =SUM(I1001:L1001) -> 0 | N1001: {=_xlfn.LET(_xlpm.total,SUM(I1001:L1001),_xlpm.maxv,MAX(I1001:L1001),IF(_xlpm.total=0,"",IF(_xlpm.maxv/_xlpm.total<0.5,"Mixed-Class",_xlfn.IFS(_xlpm.maxv=I1001,"Assault",_xlpm.maxv=J1001,"Engineer",_xlpm.maxv=K1001,"Recon",_xlpm.maxv=L1001,"Support"))))} | O1001: =_xlfn.LET(_xlpm.total,SUM(I1001:L1001),IF(_xlpm.total=0,"",MAX(I1001:L1001)/_xlpm.total>=0.5)) | P1001: =_xlfn.LET(_xlpm.total,SUM(I1001:L1001),IF(_xlpm.total=0,"",MAX(I1001:L1001)/_xlpm.total))

Sheet Global_Player_Modes
A1: Player_ID | B1: Leaderboard_Rank | C1: Conquest_Hours | D1: Escalation_Hours | E1: Breakthrough_Hours | F1: Rush_Hours | G1: TDM | H1: SDM | I1: Strikepoint | J1: Gauntlet | K1: Domination | L1: KotH | M1: Sabotage | N1: BR Quads | O1: BR Duos
A2: =Global_Players!A2 -> Stann83cz | B2: {=_xlfn.SEQUENCE(1000,1,7,10)} -> 7 | C2: 205 | D2: 19 | E2: 101 | F2: 4.5 | G2: 8 | H2: 19 | I2: 0.5 | J2: 1 | K2: 52 | L2: 228 | M2: 17 | N2: 8 | O2: 3
A3: =Global_Players!A3 -> Sir Jekyll | B3: 17 | C3: 343 | D3: 6 | E3: 103 | F3: 3.5 | G3: 4.5 | H3: 85 | I3: 0 | J3: 8 | K3: 2 | L3: 1 | M3: 1 | N3: 16 | O3: 108
A4: =Global_Players!A4 -> elkikisk | B4: 27 | C4: 201 | D4: 600 | E4: 33 | F4: 89 | G4: 0.75 | H4: 4 | I4: 0.25 | J4: 3 | K4: 4 | L4: 1 | M4: 1 | N4: 0.25 | O4: 0.1
A5: =Global_Players!A5 -> HSBxEWIKKED | B5: 37 | C5: 91 | D5: 9.25 | E5: 84 | F5: 9 | G5: 245 | H5: 105 | I5: 49 | J5: 7 | K5: 50 | L5: 95 | M5: 50 | N5: 27 | O5: 88
A6: =Global_Players!A6 -> TheBishopDeath | B6: 47 | C6: 544 | D6: 5.5 | E6: 83 | F6: 0.75 | G6: 13 | H6: 9 | I6: 4.5 | J6: 3 | K6: 4.75 | L6: 6.5 | M6: 1.25 | N6: 3 | O6: 0.75
A7: =Global_Players!A7 -> AncientWizardGuy | B7: 57 | C7: 234 | D7: 242 | E7: 237 | F7: 13 | G7: 0 | H7: 0 | I7: 0 | J7: 0 | K7: 1.25 | L7: 0.75 | M7: 0 | N7: 0 | O7: 0
A8: =Global_Players!A8 -> M5_eaglez | B8: 67 | C8: 177 | D8: 37 | E8: 453 | F8: 0.5 | G8: 0 | H8: 0 | I8: 0 | J8: 0 | K8: 0 | L8: 0.25 | M8: 0 | N8: 0 | O8: 0
A9: =Global_Players!A9 -> Ragefast2311 | B9: 77 | C9: 29 | D9: 14 | E9: 45 | F9: 4.5 | G9: 139 | H9: 52 | I9: 4 | J9: 27 | K9: 135 | L9: 4.25 | M9: 2.5 | N9: 4.25 | O9: 11
A10: =Global_Players!A10 -> xCPC464x | B10: 87 | C10: 315 | D10: 157 | E10: 135 | F10: 36 | G10: 8.25 | H10: 5.75 | I10: 6.25 | J10: 167 | K10: 9 | L10: 9.25 | M10: 11.5 | N10: 61 | O10: 67
A11: =Global_Players!A11 -> Benzo_ | B11: 97 | C11: 45 | D11: 33 | E11: 634 | F11: 1.25 | G11: 1.75 | H11: 0 | I11: 0 | J11: 5 | K11: 3 | L11: 1.75 | M11: 0 | N11: 8.25 | O11: 12
A12: =Global_Players!A12 -> rgayregger | B12: 107 | C12: 80 | D12: 42 | E12: 138 | F12: 25 | G12: 4 | H12: 2 | I12: 2.5 | J12: 0 | K12: 55 | L12: 54 | M12: 6 | N12: 0.75 | O12: 0.25
A13: =Global_Players!A13 -> 0 | B13: 117
A14: =Global_Players!A14 -> 0 | B14: 127
A15: =Global_Players!A15 -> 0 | B15: 137
A16: =Global_Players!A16 -> 0 | B16: 147
A17: =Global_Players!A17 -> 0 | B17: 157
A18: =Global_Players!A18 -> 0 | B18: 167
A19: =Global_Players!A19 -> 0 | B19: 177
A20: =Global_Players!A20 -> 0 | B20: 187
A21: =Global_Players!A21 -> 0 | B21: 197
A22: =Global_Players!A22 -> 0 | B22: 207
A23: =Global_Players!A23 -> 0 | B23: 217
A24: =Global_Players!A24 -> 0 | B24: 227
... A38: =Global_Players!A38 -> 0 | B38: 367
B39: 377
B40: 387
B41: 397
B42: 407
B43: 417
B44: 427
B45: 437
B46: 447
B47: 457
B48: 467
B49: 477
B50: 487
... B1001: 9997

Sheet Class_Players
A1: Player_ID | B1: Class | C1: Class_Row_Index | D1: Leaderboard_Rank | E1: Rank_Segment | F1: Class_Deployments | G1: Class_Time_Hour | H1: Snapshot_Date | I1: Duplicate_Key
A2: mirovampiro | B2: Assault | C2: =IF(ROW()=2,1,IF(B2<>B1,1,C1+1)) -> 1 | D2: {=_xlfn.IFS(C2<=50,7+10*(C2-1),C2<=110,507+25*(C2-51),C2<=170,2007+50*(C2-111),C2<=250,5007+50*(C2-171))} -> 7 | E2: {=IF(D2="","",_xlfn.IFS(D2<=500,"Top_500",D2<=2000,"501_2000",D2<=5000,"2001_5000",D2<=10000,"5001_10000"))} -> Top_500 | F2: 28809 | G2: 491 | H2: 46046 | I2: =A2 & "|" & B2 -> mirovampiro|Assault
A3: Francko Escobar | B3: Assault | C3: =IF(ROW()=2,1,IF(B3<>B2,1,C2+1)) -> 2 | D3: {=_xlfn.IFS(C3<=50,7+10*(C3-1),C3<=110,507+25*(C3-51),C3<=170,2007+50*(C3-111),C3<=250,5007+50*(C3-171))} -> 17 | E3: {=IF(D3="","",_xlfn.IFS(D3<=500,"Top_500",D3<=2000,"501_2000",D3<=5000,"2001_5000",D3<=10000,"5001_10000"))} -> Top_500 | F3: 22167 | G3: 388 | H3: 46048 | I3: =A3 & "|" & B3 -> Francko Escobar|Assault
A4: CFGBOT | B4: Assault | C4: =IF(ROW()=2,1,IF(B4<>B3,1,C3+1)) -> 3 | D4: {=_xlfn.IFS(C4<=50,7+10*(C4-1),C4<=110,507+25*(C4-51),C4<=170,2007+50*(C4-111),C4<=250,5007+50*(C4-171))} -> 27 | E4: {=IF(D4="","",_xlfn.IFS(D4<=500,"Top_500",D4<=2000,"501_2000",D4<=5000,"2001_5000",D4<=10000,"5001_10000"))} -> Top_500 | F4: 21125 | G4: 351 | H4: 46048 | I4: =A4 & "|" & B4 -> CFGBOT|Assault
A5: avengerhawk | B5: Assault | C5: =IF(ROW()=2,1,IF(B5<>B4,1,C4+1)) -> 4 | D5: {=_xlfn.IFS(C5<=50,7+10*(C5-1),C5<=110,507+25*(C5-51),C5<=170,2007+50*(C5-111),C5<=250,5007+50*(C5-171))} -> 37 | E5: {=IF(D5="","",_xlfn.IFS(D5<=500,"Top_500",D5<=2000,"501_2000",D5<=5000,"2001_5000",D5<=10000,"5001_10000"))} -> Top_500 | F5: 20105 | G5: 258 | H5: 46048 | I5: =A5 & "|" & B5 -> avengerhawk|Assault
A6: Chopppppperrrrr | B6: Assault | C6: =IF(ROW()=2,1,IF(B6<>B5,1,C5+1)) -> 5 | D6: {=_xlfn.IFS(C6<=50,7+10*(C6-1),C6<=110,507+25*(C6-51),C6<=170,2007+50*(C6-111),C6<=250,5007+50*(C6-171))} -> 47 | E6: {=IF(D6="","",_xlfn.IFS(D6<=500,"Top_500",D6<=2000,"501_2000",D6<=5000,"2001_5000",D6<=10000,"5001_10000"))} -> Top_500 | F6: 18236 | G6: 157 | H6: 46048 | I6: =A6 & "|" & B6 -> Chopppppperrrrr|Assault
A7: d00hn!e+ | B7: Assault | C7: =IF(ROW()=2,1,IF(B7<>B6,1,C6+1)) -> 6 | D7: {=_xlfn.IFS(C7<=50,7+10*(C7-1),C7<=110,507+25*(C7-51),C7<=170,2007+50*(C7-111),C7<=250,5007+50*(C7-171))} -> 57 | E7: {=IF(D7="","",_xlfn.IFS(D7<=500,"Top_500",D7<=2000,"501_2000",D7<=5000,"2001_5000",D7<=10000,"5001_10000"))} -> Top_500 | F7: 17549 | G7: 350 | H7: 46048 | I7: =A7 & "|" & B7 -> d00hn!e+|Assault
A8: Wiesiu_PL | B8: Assault | C8: =IF(ROW()=2,1,IF(B8<>B7,1,C7+1)) -> 7 | D8: {=_xlfn.IFS(C8<=50,7+10*(C8-1),C8<=110,507+25*(C8-51),C8<=170,2007+50*(C8-111),C8<=250,5007+50*(C8-171))} -> 67 | E8: {=IF(D8="","",_xlfn.IFS(D8<=500,"Top_500",D8<=2000,"501_2000",D8<=5000,"2001_5000",D8<=10000,"5001_10000"))} -> Top_500 | F8: 16810 | G8: 307 | H8: 46048 | I8: =A8 & "|" & B8 -> Wiesiu_PL|Assault
A9: Nathanchor | B9: Assault | C9: =IF(ROW()=2,1,IF(B9<>B8,1,C8+1)) -> 8 | D9: {=_xlfn.IFS(C9<=50,7+10*(C9-1),C9<=110,507+25*(C9-51),C9<=170,2007+50*(C9-111),C9<=250,5007+50*(C9-171))} -> 77 | E9: {=IF(D9="","",_xlfn.IFS(D9<=500,"Top_500",D9<=2000,"501_2000",D9<=5000,"2001_5000",D9<=10000,"5001_10000"))} -> Top_500 | F9: 16195 | G9: 317 | H9: 46048 | I9: =A9 & "|" & B9 -> Nathanchor|Assault
A10: Sempire90 | B10: Assault | C10: =IF(ROW()=2,1,IF(B10<>B9,1,C9+1)) -> 9 | D10: {=_xlfn.IFS(C10<=50,7+10*(C10-1),C10<=110,507+25*(C10-51),C10<=170,2007+50*(C10-111),C10<=250,5007+50*(C10-171))} -> 87 | E10: {=IF(D10="","",_xlfn.IFS(D10<=500,"Top_500",D10<=2000,"501_2000",D10<=5000,"2001_5000",D10<=10000,"5001_10000"))} -> Top_500 | F10: 15789 | G10: 159 | H10: 46048 | I10: =A10 & "|" & B10 -> Sempire90|Assault
A11: frothandbubble | B11: Assault | C11: =IF(ROW()=2,1,IF(B11<>B10,1,C10+1)) -> 10 | D11: {=_xlfn.IFS(C11<=50,7+10*(C11-1),C11<=110,507+25*(C11-51),C11<=170,2007+50*(C11-111),C11<=250,5007+50*(C11-171))} -> 97 | E11: {=IF(D11="","",_xlfn.IFS(D11<=500,"Top_500",D11<=2000,"501_2000",D11<=5000,"2001_5000",D11<=10000,"5001_10000"))} -> Top_500 | F11: 15912 | G11: 393 | H11: 46048 | I11: =A11 & "|" & B11 -> frothandbubble|Assault
A12: VARIIANT99 | B12: Assault | C12: =IF(ROW()=2,1,IF(B12<>B11,1,C11+1)) -> 11 | D12: {=_xlfn.IFS(C12<=50,7+10*(C12-1),C12<=110,507+25*(C12-51),C12<=170,2007+50*(C12-111),C12<=250,5007+50*(C12-171))} -> 107 | E12: {=IF(D12="","",_xlfn.IFS(D12<=500,"Top_500",D12<=2000,"501_2000",D12<=5000,"2001_5000",D12<=10000,"5001_10000"))} -> Top_500 | F12: 15421 | G12: 252 | H12: 46049 | I12: =A12 & "|" & B12 -> VARIIANT99|Assault
A13: Plasem | B13: Assault | C13: =IF(ROW()=2,1,IF(B13<>B12,1,C12+1)) -> 12 | D13: {=_xlfn.IFS(C13<=50,7+10*(C13-1),C13<=110,507+25*(C13-51),C13<=170,2007+50*(C13-111),C13<=250,5007+50*(C13-171))} -> 117 | E13: {=IF(D13="","",_xlfn.IFS(D13<=500,"Top_500",D13<=2000,"501_2000",D13<=5000,"2001_5000",D13<=10000,"5001_10000"))} -> Top_500 | F13: 14952 | G13: 381 | H13: 46049 | I13: =A13 & "|" & B13 -> Plasem|Assault
... A101: ARMIS-INVAR-RUSH | B101: Assault | C101: =IF(ROW()=2,1,IF(B101<>B100,1,C100+1)) -> 100 | D101: {=_xlfn.IFS(C101<=50,7+10*(C101-1),C101<=110,507+25*(C101-51),C101<=170,2007+50*(C101-111),C101<=250,5007+50*(C101-171))} -> 1732 | E101: {=IF(D101="","",_xlfn.IFS(D101<=500,"Top_500",D101<=2000,"501_2000",D101<=5000,"2001_5000",D101<=10000,"5001_10000"))} -> 501_2000 | F101: 7175 | G101: 107 | H101: 46051 | I101: =A101 & "|" & B101 -> ARMIS-INVAR-RUSH|Assault
B102: Assault | C102: =IF(ROW()=2,1,IF(B102<>B101,1,C101+1)) -> 101 | D102: {=_xlfn.IFS(C102<=50,7+10*(C102-1),C102<=110,507+25*(C102-51),C102<=170,2007+50*(C102-111),C102<=250,5007+50*(C102-171))} -> 1757 | E102: {=IF(D102="","",_xlfn.IFS(D102<=500,"Top_500",D102<=2000,"501_2000",D102<=5000,"2001_5000",D102<=10000,"5001_10000"))} -> 501_2000 | I102: =A102 & "|" & B102 -> |Assault
B103: Assault | C103: =IF(ROW()=2,1,IF(B103<>B102,1,C102+1)) -> 102 | D103: {=_xlfn.IFS(C103<=50,7+10*(C103-1),C103<=110,507+25*(C103-51),C103<=170,2007+50*(C103-111),C103<=250,5007+50*(C103-171))} -> 1782 | E103: {=IF(D103="","",_xlfn.IFS(D103<=500,"Top_500",D103<=2000,"501_2000",D103<=5000,"2001_5000",D103<=10000,"5001_10000"))} -> 501_2000 | I103: =A103 & "|" & B103 -> |Assault
B104: Assault | C104: =IF(ROW()=2,1,IF(B104<>B103,1,C103+1)) -> 103 | D104: {=_xlfn.IFS(C104<=50,7+10*(C104-1),C104<=110,507+25*(C104-51),C104<=170,2007+50*(C104-111),C104<=250,5007+50*(C104-171))} -> 1807 | E104: {=IF(D104="","",_xlfn.IFS(D104<=500,"Top_500",D104<=2000,"501_2000",D104<=5000,"2001_5000",D104<=10000,"5001_10000"))} -> 501_2000 | I104: =A104 & "|" & B104 -> |Assault
B105: Assault | C105: =IF(ROW()=2,1,IF(B105<>B104,1,C104+1)) -> 104 | D105: {=_xlfn.IFS(C105<=50,7+10*(C105-1),C105<=110,507+25*(C105-51),C105<=170,2007+50*(C105-111),C105<=250,5007+50*(C105-171))} -> 1832 | E105: {=IF(D105="","",_xlfn.IFS(D105<=500,"Top_500",D105<=2000,"501_2000",D105<=5000,"2001_5000",D105<=10000,"5001_10000"))} -> 501_2000 | I105: =A105 & "|" & B105 -> |Assault
B106: Assault | C106: =IF(ROW()=2,1,IF(B106<>B105,1,C105+1)) -> 105 | D106: {=_xlfn.IFS(C106<=50,7+10*(C106-1),C106<=110,507+25*(C106-51),C106<=170,2007+50*(C106-111),C106<=250,5007+50*(C106-171))} -> 1857 | E106: {=IF(D106="","",_xlfn.IFS(D106<=500,"Top_500",D106<=2000,"501_2000",D106<=5000,"2001_5000",D106<=10000,"5001_10000"))} -> 501_2000 | I106: =A106 & "|" & B106 -> |Assault
B107: Assault | C107: =IF(ROW()=2,1,IF(B107<>B106,1,C106+1)) -> 106 | D107: {=_xlfn.IFS(C107<=50,7+10*(C107-1),C107<=110,507+25*(C107-51),C107<=170,2007+50*(C107-111),C107<=250,5007+50*(C107-171))} -> 1882 | E107: {=IF(D107="","",_xlfn.IFS(D107<=500,"Top_500",D107<=2000,"501_2000",D107<=5000,"2001_5000",D107<=10000,"5001_10000"))} -> 501_2000 | I107: =A107 & "|" & B107 -> |Assault
B108: Assault | C108: =IF(ROW()=2,1,IF(B108<>B107,1,C107+1)) -> 107 | D108: {=_xlfn.IFS(C108<=50,7+10*(C108-1),C108<=110,507+25*(C108-51),C108<=170,2007+50*(C108-111),C108<=250,5007+50*(C108-171))} -> 1907 | E108: {=IF(D108="","",_xlfn.IFS(D108<=500,"Top_500",D108<=2000,"501_2000",D108<=5000,"2001_5000",D108<=10000,"5001_10000"))} -> 501_2000 | I108: =A108 & "|" & B108 -> |Assault
B109: Assault | C109: =IF(ROW()=2,1,IF(B109<>B108,1,C108+1)) -> 108 | D109: {=_xlfn.IFS(C109<=50,7+10*(C109-1),C109<=110,507+25*(C109-51),C109<=170,2007+50*(C109-111),C109<=250,5007+50*(C109-171))} -> 1932 | E109: {=IF(D109="","",_xlfn.IFS(D109<=500,"Top_500",D109<=2000,"501_2000",D109<=5000,"2001_5000",D109<=10000,"5001_10000"))} -> 501_2000 | I109: =A109 & "|" & B109 -> |Assault
B110: Assault | C110: =IF(ROW()=2,1,IF(B110<>B109,1,C109+1)) -> 109 | D110: {=_xlfn.IFS(C110<=50,7+10*(C110-1),C110<=110,507+25*(C110-51),C110<=170,2007+50*(C110-111),C110<=250,5007+50*(C110-171))} -> 1957 | E110: {=IF(D110="","",_xlfn.IFS(D110<=500,"Top_500",D110<=2000,"501_2000",D110<=5000,"2001_5000",D110<=10000,"5001_10000"))} -> 501_2000 | I110: =A110 & "|" & B110 -> |Assault
B111: Assault | C111: =IF(ROW()=2,1,IF(B111<>B110,1,C110+1)) -> 110 | D111: {=_xlfn.IFS(C111<=50,7+10*(C111-1),C111<=110,507+25*(C111-51),C111<=170,2007+50*(C111-111),C111<=250,5007+50*(C111-171))} -> 1982 | E111: {=IF(D111="","",_xlfn.IFS(D111<=500,"Top_500",D111<=2000,"501_2000",D111<=5000,"2001_5000",D111<=10000,"5001_10000"))} -> 501_2000 | I111: =A111 & "|" & B111 -> |Assault
B112: Assault | C112: =IF(ROW()=2,1,IF(B112<>B111,1,C111+1)) -> 111 | D112: {=_xlfn.IFS(C112<=50,7+10*(C112-1),C112<=110,507+25*(C112-51),C112<=170,2007+50*(C112-111),C112<=250,5007+50*(C112-171))} -> 2007 | E112: {=IF(D112="","",_xlfn.IFS(D112<=500,"Top_500",D112<=2000,"501_2000",D112<=5000,"2001_5000",D112<=10000,"5001_10000"))} -> 2001_5000 | I112: =A112 & "|" & B112 -> |Assault
B113: Assault | C113: =IF(ROW()=2,1,IF(B113<>B112,1,C112+1)) -> 112 | D113: {=_xlfn.IFS(C113<=50,7+10*(C113-1),C113<=110,507+25*(C113-51),C113<=170,2007+50*(C113-111),C113<=250,5007+50*(C113-171))} -> 2057 | E113: {=IF(D113="","",_xlfn.IFS(D113<=500,"Top_500",D113<=2000,"501_2000",D113<=5000,"2001_5000",D113<=10000,"5001_10000"))} -> 2001_5000 | I113: =A113 & "|" & B113 -> |Assault
... B251: Assault | C251: =IF(ROW()=2,1,IF(B251<>B250,1,C250+1)) -> 250 | D251: {=_xlfn.IFS(C251<=50,7+10*(C251-1),C251<=110,507+25*(C251-51),C251<=170,2007+50*(C251-111),C251<=250,5007+50*(C251-171))} -> 8957 | E251: {=IF(D251="","",_xlfn.IFS(D251<=500,"Top_500",D251<=2000,"501_2000",D251<=5000,"2001_5000",D251<=10000,"5001_10000"))} -> 5001_10000 | I251: =A251 & "|" & B251 -> |Assault
A252: gym-imperator-ju | B252: Engineer | C252: =IF(ROW()=2,1,IF(B252<>B251,1,C251+1)) -> 1 | D252: {=_xlfn.IFS(C252<=50,7+10*(C252-1),C252<=110,507+25*(C252-51),C252<=170,2007+50*(C252-111),C252<=250,5007+50*(C252-171))} -> 7 | E252: {=IF(D252="","",_xlfn.IFS(D252<=500,"Top_500",D252<=2000,"501_2000",D252<=5000,"2001_5000",D252<=10000,"5001_10000"))} -> Top_500 | F252: 21734 | G252: 299 | H252: 46048 | I252: =A252 & "|" & B252 -> gym-imperator-ju|Engineer
A253: Samyt4040 | B253: Engineer | C253: =IF(ROW()=2,1,IF(B253<>B252,1,C252+1)) -> 2 | D253: {=_xlfn.IFS(C253<=50,7+10*(C253-1),C253<=110,507+25*(C253-51),C253<=170,2007+50*(C253-111),C253<=250,5007+50*(C253-171))} -> 17 | E253: {=IF(D253="","",_xlfn.IFS(D253<=500,"Top_500",D253<=2000,"501_2000",D253<=5000,"2001_5000",D253<=10000,"5001_10000"))} -> Top_500 | F253: 18459 | G253: 145 | H253: 46048 | I253: =A253 & "|" & B253 -> Samyt4040|Engineer
A254: Dc-Duck | B254: Engineer | C254: =IF(ROW()=2,1,IF(B254<>B253,1,C253+1)) -> 3 | D254: {=_xlfn.IFS(C254<=50,7+10*(C254-1),C254<=110,507+25*(C254-51),C254<=170,2007+50*(C254-111),C254<=250,5007+50*(C254-171))} -> 27 | E254: {=IF(D254="","",_xlfn.IFS(D254<=500,"Top_500",D254<=2000,"501_2000",D254<=5000,"2001_5000",D254<=10000,"5001_10000"))} -> Top_500 | F254: 16655 | G254: 399 | H254: 46048 | I254: =A254 & "|" & B254 -> Dc-Duck|Engineer
A255: BIGBaNANaBender | B255: Engineer | C255: =IF(ROW()=2,1,IF(B255<>B254,1,C254+1)) -> 4 | D255: {=_xlfn.IFS(C255<=50,7+10*(C255-1),C255<=110,507+25*(C255-51),C255<=170,2007+50*(C255-111),C255<=250,5007+50*(C255-171))} -> 37 | E255: {=IF(D255="","",_xlfn.IFS(D255<=500,"Top_500",D255<=2000,"501_2000",D255<=5000,"2001_5000",D255<=10000,"5001_10000"))} -> Top_500 | F255: 15761 | G255: 310 | H255: 46048 | I255: =A255 & "|" & B255 -> BIGBaNANaBender|Engineer
A256: tangsifuuu | B256: Engineer | C256: =IF(ROW()=2,1,IF(B256<>B255,1,C255+1)) -> 5 | D256: {=_xlfn.IFS(C256<=50,7+10*(C256-1),C256<=110,507+25*(C256-51),C256<=170,2007+50*(C256-111),C256<=250,5007+50*(C256-171))} -> 47 | E256: {=IF(D256="","",_xlfn.IFS(D256<=500,"Top_500",D256<=2000,"501_2000",D256<=5000,"2001_5000",D256<=10000,"5001_10000"))} -> Top_500 | F256: 15141 | G256: 357 | H256: 46048 | I256: =A256 & "|" & B256 -> tangsifuuu|Engineer
A257: |bulletproof64 | B257: Engineer | C257: =IF(ROW()=2,1,IF(B257<>B256,1,C256+1)) -> 6 | D257: {=_xlfn.IFS(C257<=50,7+10*(C257-1),C257<=110,507+25*(C257-51),C257<=170,2007+50*(C257-111),C257<=250,5007+50*(C257-171))} -> 57 | E257: {=IF(D257="","",_xlfn.IFS(D257<=500,"Top_500",D257<=2000,"501_2000",D257<=5000,"2001_5000",D257<=10000,"5001_10000"))} -> Top_500 | F257: 14038 | G257: 176 | H257: 46048 | I257: =A257 & "|" & B257 -> |bulletproof64|Engineer
A258: SilverBullet479 | B258: Engineer | C258: =IF(ROW()=2,1,IF(B258<>B257,1,C257+1)) -> 7 | D258: {=_xlfn.IFS(C258<=50,7+10*(C258-1),C258<=110,507+25*(C258-51),C258<=170,2007+50*(C258-111),C258<=250,5007+50*(C258-171))} -> 67 | E258: {=IF(D258="","",_xlfn.IFS(D258<=500,"Top_500",D258<=2000,"501_2000",D258<=5000,"2001_5000",D258<=10000,"5001_10000"))} -> Top_500 | F258: 14557 | G258: 301 | H258: 46048 | I258: =A258 & "|" & B258 -> SilverBullet479|Engineer
A259: Formerly_AL | B259: Engineer | C259: =IF(ROW()=2,1,IF(B259<>B258,1,C258+1)) -> 8 | D259: {=_xlfn.IFS(C259<=50,7+10*(C259-1),C259<=110,507+25*(C259-51),C259<=170,2007+50*(C259-111),C259<=250,5007+50*(C259-171))} -> 77 | E259: {=IF(D259="","",_xlfn.IFS(D259<=500,"Top_500",D259<=2000,"501_2000",D259<=5000,"2001_5000",D259<=10000,"5001_10000"))} -> Top_500 | F259: 13465 | G259: 274 | H259: 46048 | I259: =A259 & "|" & B259 -> Formerly_AL|Engineer
A260: OleksandrEighty9 | B260: Engineer | C260: =IF(ROW()=2,1,IF(B260<>B259,1,C259+1)) -> 9 | D260: {=_xlfn.IFS(C260<=50,7+10*(C260-1),C260<=110,507+25*(C260-51),C260<=170,2007+50*(C260-111),C260<=250,5007+50*(C260-171))} -> 87 | E260: {=IF(D260="","",_xlfn.IFS(D260<=500,"Top_500",D260<=2000,"501_2000",D260<=5000,"2001_5000",D260<=10000,"5001_10000"))} -> Top_500 | F260: 13276 | G260: 388 | H260: 46048 | I260: =A260 & "|" & B260 -> OleksandrEighty9|Engineer
A261: CubanMafia | B261: Engineer | C261: =IF(ROW()=2,1,IF(B261<>B260,1,C260+1)) -> 10 | D261: {=_xlfn.IFS(C261<=50,7+10*(C261-1),C261<=110,507+25*(C261-51),C261<=170,2007+50*(C261-111),C261<=250,5007+50*(C261-171))} -> 97 | E261: {=IF(D261="","",_xlfn.IFS(D261<=500,"Top_500",D261<=2000,"501_2000",D261<=5000,"2001_5000",D261<=10000,"5001_10000"))} -> Top_500 | F261: 13737 | G261: 346 | H261: 46048 | I261: =A261 & "|" & B261 -> CubanMafia|Engineer
A262: NooterzXD | B262: Engineer | C262: =IF(ROW()=2,1,IF(B262<>B261,1,C261+1)) -> 11 | D262: {=_xlfn.IFS(C262<=50,7+10*(C262-1),C262<=110,507+25*(C262-51),C262<=170,2007+50*(C262-111),C262<=250,5007+50*(C262-171))} -> 107 | E262: {=IF(D262="","",_xlfn.IFS(D262<=500,"Top_500",D262<=2000,"501_2000",D262<=5000,"2001_5000",D262<=10000,"5001_10000"))} -> Top_500 | F262: 12749 | G262: 293 | H262: 46049 | I262: =A262 & "|" & B262 -> NooterzXD|Engineer
A263: ylari | B263: Engineer | C263: =IF(ROW()=2,1,IF(B263<>B262,1,C262+1)) -> 12 | D263: {=_xlfn.IFS(C263<=50,7+10*(C263-1),C263<=110,507+25*(C263-51),C263<=170,2007+50*(C263-111),C263<=250,5007+50*(C263-171))} -> 117 | E263: {=IF(D263="","",_xlfn.IFS(D263<=500,"Top_500",D263<=2000,"501_2000",D263<=5000,"2001_5000",D263<=10000,"5001_10000"))} -> Top_500 | F263: 15188 | G263: 213 | H263: 46049 | I263: =A263 & "|" & B263 -> ylari|Engineer
... A351: II STRICK9 II | B351: Engineer | C351: =IF(ROW()=2,1,IF(B351<>B350,1,C350+1)) -> 100 | D351: {=_xlfn.IFS(C351<=50,7+10*(C351-1),C351<=110,507+25*(C351-51),C351<=170,2007+50*(C351-111),C351<=250,5007+50*(C351-171))} -> 1732 | E351: {=IF(D351="","",_xlfn.IFS(D351<=500,"Top_500",D351<=2000,"501_2000",D351<=5000,"2001_5000",D351<=10000,"5001_10000"))} -> 501_2000 | F351: 6773 | G351: 233 | H351: 46052 | I351: =A351 & "|" & B351 -> II STRICK9 II|Engineer
...

Sheet Gadget_Usage_Assault
A1: Player_ID | B1: Class | C1: Gadget_Name | D1: Equipment_Type | E1: Usage_Count | F1: Class_Time_Hour | G1: Uses_Per_Hour | H1: Class_Deployments | I1: Uses_Per_Deployment | J1: Select_Flag | K1: Selection_Weight | L1: Gadget_Share
A2: {=IFERROR(INDEX(_xlfn._xlws.FILTER(Class_Players!A:A,Class_Players!B:B="Assault"),QUOTIENT(ROW()-ROW($A$2),7)+1),"")} -> mirovampiro | B2: =_xlfn.XLOOKUP(A2,Class_Players!$A:$A,Class_Players!$B:$B,"") -> Assault | C2: {=INDEX(Lookups!$A$2:$A$8,MOD(ROW()-ROW($B$2),ROWS(Lookups!$A$2:$A$8))+1)} -> Assault Ladder | D2: =_xlfn.XLOOKUP(C2,Analysis_Gadgets!$C:$C,Analysis_Gadgets!$B:$B) -> Gadget | E2: 98 | F2: =_xlfn.XLOOKUP(A2,Class_Players!A:A,Class_Players!G:G) -> 491 | G2: =IF(F2=0,"",E2/F2) -> 0.19959267 | H2: =_xlfn.XLOOKUP(A2,Class_Players!$A:$A,Class_Players!$F:$F,"") -> 28809 | I2: =IF(H2=0,"",E2/H2) -> 0.0034017147 | J2: =IF(I2>=0.1,1,0) -> 0 | K2: {=IF(D2="Gadget",_xlfn.IFS(I2>=0.2,0.5,I2>=0.1,0.35,I2>=0.05,0.2,TRUE,0),IF(D2="Grenade",_xlfn.IFS(I2>=0.2,1,I2>=0.1,0.7,I2>=0.05,0.4,TRUE,0),0))} -> 0 | L2: =IF($K2=0,0,$K2 / SUMIFS($K:$K,$A:$A,$A2,$D:$D,"Gadget")) -> 0
A3: {=IFERROR(INDEX(_xlfn._xlws.FILTER(Class_Players!A:A,Class_Players!B:B="Assault"),QUOTIENT(ROW()-ROW($A$2),7)+1),"")} -> mirovampiro | B3: =_xlfn.XLOOKUP(A3,Class_Players!$A:$A,Class_Players!$B:$B,"") -> Assault | C3: {=INDEX(Lookups!$A$2:$A$8,MOD(ROW()-ROW($B$2),ROWS(Lookups!$A$2:$A$8))+1)} -> X95 BRE (Breaching Projectile Launcher) | D3: =_xlfn.XLOOKUP(C3,Analysis_Gadgets!$C:$C,Analysis_Gadgets!$B:$B) -> Gadget | E3: 0 | F3: =_xlfn.XLOOKUP(A3,Class_Players!A:A,Class_Players!G:G) -> 491 | G3: =IF(F3=0,"",E3/F3) -> 0 | H3: =_xlfn.XLOOKUP(A3,Class_Players!$A:$A,Class_Players!$F:$F,"") -> 28809 | I3: =IF(H3=0,"",E3/H3) -> 0 | J3: =IF(I3>=0.1,1,0) -> 0 | K3: {=IF(D3="Gadget",_xlfn.IFS(I3>=0.2,0.5,I3>=0.1,0.35,I3>=0.05,0.2,TRUE,0),IF(D3="Grenade",_xlfn.IFS(I3>=0.2,1,I3>=0.1,0.7,I3>=0.05,0.4,TRUE,0),0))} -> 0 | L3: =IF($K3=0,0,$K3 / SUMIFS($K:$K,$A:$A,$A3,$D:$D,"Gadget")) -> 0
A4: {=IFERROR(INDEX(_xlfn._xlws.FILTER(Class_Players!A:A,Class_Players!B:B="Assault"),QUOTIENT(ROW()-ROW($A$2),7)+1),"")} -> mirovampiro | B4: =_xlfn.XLOOKUP(A4,Class_Players!$A:$A,Class_Players!$B:$B,"") -> Assault | C4: {=INDEX(Lookups!$A$2:$A$8,MOD(ROW()-ROW($B$2),ROWS(Lookups!$A$2:$A$8))+1)} -> M320A1 HE (Grenade Launcher) | D4: =_xlfn.XLOOKUP(C4,Analysis_Gadgets!$C:$C,Analysis_Gadgets!$B:$B) -> Gadget | E4: 2791 | F4: =_xlfn.XLOOKUP(A4,Class_Players!A:A,Class_Players!G:G) -> 491 | G4: =IF(F4=0,"",E4/F4) -> 5.6843177 | H4: =_xlfn.XLOOKUP(A4,Class_Players!$A:$A,Class_Players!$F:$F,"") -> 28809 | I4: =IF(H4=0,"",E4/H4) -> 0.096879447 | J4: =IF(I4>=0.1,1,0) -> 0 | K4: {=IF(D4="Gadget",_xlfn.IFS(I4>=0.2,0.5,I4>=0.1,0.35,I4>=0.05,0.2,TRUE,0),IF(D4="Grenade",_xlfn.IFS(I4>=0.2,1,I4>=0.1,0.7,I4>=0.05,0.4,TRUE,0),0))} -> 0.2 | L4: =IF($K4=0,0,$K4 / SUMIFS($K:$K,$A:$A,$A4,$D:$D,"Gadget")) -> 0.36363636
A5: {=IFERROR(INDEX(_xlfn._xlws.FILTER(Class_Players!A:A,Class_Players!B:B="Assault"),QUOTIENT(ROW()-ROW($A$2),7)+1),"")} -> mirovampiro | B5: =_xlfn.XLOOKUP(A5,Class_Players!$A:$A,Class_Players!$B:$B,"") -> Assault | C5: {=INDEX(Lookups!$A$2:$A$8,MOD(ROW()-ROW($B$2),ROWS(Lookups!$A$2:$A$8))+1)} -> M320A1 THRM (Incendiary Grenade Launcher) | D5: =_xlfn.XLOOKUP(C5,Analysis_Gadgets!$C:$C,Analysis_Gadgets!$B:$B) -> Gadget | E5: 33 | F5: =_xlfn.XLOOKUP(A5,Class_Players!A:A,Class_Players!G:G) -> 491 | G5: =IF(F5=0,"",E5/F5) -> 0.067209776 | H5: =_xlfn.XLOOKUP(A5,Class_Players!$A:$A,Class_Players!$F:$F,"") -> 28809 | I5: =IF(H5=0,"",E5/H5) -> 0.0011454754 | J5: =IF(I5>=0.1,1,0) -> 0 | K5: {=IF(D5="Gadget",_xlfn.IFS(I5>=0.2,0.5,I5>=0.1,0.35,I5>=0.05,0.2,TRUE,0),IF(D5="Grenade",_xlfn.IFS(I5>=0.2,1,I5>=0.1,0.7,I5>=0.05,0.4,TRUE,0),0))} -> 0 | L5: =IF($K5=0,0,$K5 / SUMIFS($K:$K,$A:$A,$A5,$D:$D,"Gadget")) -> 0
A6: {=IFERROR(INDEX(_xlfn._xlws.FILTER(Class_Players!A:A,Class_Players!B:B="Assault"),QUOTIENT(ROW()-ROW($A$2),7)+1),"")} -> mirovampiro | B6: =_xlfn.XLOOKUP(A6,Class_Players!$A:$A,Class_Players!$B:$B,"") -> Assault | C6: {=INDEX(Lookups!$A$2:$A$8,MOD(ROW()-ROW($B$2),ROWS(Lookups!$A$2:$A$8))+1)} -> QLINK (Deploy Beacon) | D6: =_xlfn.XLOOKUP(C6,Analysis_Gadgets!$C:$C,Analysis_Gadgets!$B:$B) -> Gadget | E6: 5283 | F6: =_xlfn.XLOOKUP(A6,Class_Players!A:A,Class_Players!G:G) -> 491 | G6: =IF(F6=0,"",E6/F6) -> 10.759674 | H6: =_xlfn.XLOOKUP(A6,Class_Players!$A:$A,Class_Players!$F:$F,"") -> 28809 | I6: =IF(H6=0,"",E6/H6) -> 0.18338019 | J6: =IF(I6>=0.1,1,0) -> 1 | K6: {=IF(D6="Gadget",_xlfn.IFS(I6>=0.2,0.5,I6>=0.1,0.35,I6>=0.05,0.2,TRUE,0),IF(D6="Grenade",_xlfn.IFS(I6>=0.2,1,I6>=0.1,0.7,I6>=0.05,0.4,TRUE,0),0))} -> 0.35 | L6: =IF($K6=0,0,$K6 / SUMIFS($K:$K,$A:$A,$A6,$D:$D,"Gadget")) -> 0.63636364
A7: {=IFERROR(INDEX(_xlfn._xlws.FILTER(Class_Players!A:A,Class_Players!B:B="Assault"),QUOTIENT(ROW()-ROW($A$2),7)+1),"")} -> mirovampiro | B7: =_xlfn.XLOOKUP(A7,Class_Players!$A:$A,Class_Players!$B:$B,"") -> Assault | C7: {=INDEX(Lookups!$A$2:$A$8,MOD(ROW()-ROW($B$2),ROWS(Lookups!$A$2:$A$8))+1)} -> Stun Grenade | D7: =_xlfn.XLOOKUP(C7,Analysis_Gadgets!$C:$C,Analysis_Gadgets!$B:$B) -> Grenade | E7: 105 | F7: =_xlfn.XLOOKUP(A7,Class_Players!A:A,Class_Players!G:G) -> 491 | G7: =IF(F7=0,"",E7/F7) -> 0.21384929 | H7: =_xlfn.XLOOKUP(A7,Class_Players!$A:$A,Class_Players!$F:$F,"") -> 28809 | I7: =IF(H7=0,"",E7/H7) -> 0.0036446944 | J7: =IF(I7>=0.1,1,0) -> 0 | K7: {=IF(D7="Gadget",_xlfn.IFS(I7>=0.2,0.5,I7>=0.1,0.35,I7>=0.05,0.2,TRUE,0),IF(D7="Grenade",_xlfn.IFS(I7>=0.2,1,I7>=0.1,0.7,I7>=0.05,0.4,TRUE,0),0))} -> 0 | L7: =IF($K7=0,0,$K7 / SUMIFS($K:$K,$A:$A,$A7,$D:$D,"Grenade")) -> 0
A8: {=IFERROR(INDEX(_xlfn._xlws.FILTER(Class_Players!A:A,Class_Players!B:B="Assault"),QUOTIENT(ROW()-ROW($A$2),7)+1),"")} -> mirovampiro | B8: =_xlfn.XLOOKUP(A8,Class_Players!$A:$A,Class_Players!$B:$B,"") -> Assault | C8: {=INDEX(Lookups!$A$2:$A$8,MOD(ROW()-ROW($B$2),ROWS(Lookups!$A$2:$A$8))+1)} -> Flash Grenade | D8: =_xlfn.XLOOKUP(C8,Analysis_Gadgets!$C:$C,Analysis_Gadgets!$B:$B) -> Grenade | E8: 71 | F8: =_xlfn.XLOOKUP(A8,Class_Players!A:A,Class_Players!G:G) -> 491 | G8: =IF(F8=0,"",E8/F8) -> 0.14460285 | H8: =_xlfn.XLOOKUP(A8,Class_Players!$A:$A,Class_Players!$F:$F,"") -> 28809 | I8: =IF(H8=0,"",E8/H8) -> 0.0024645076 | J8: =IF(I8>=0.1,1,0) -> 0 | K8: {=IF(D8="Gadget",_xlfn.IFS(I8>=0.2,0.5,I8>=0.1,0.35,I8>=0.05,0.2,TRUE,0),IF(D8="Grenade",_xlfn.IFS(I8>=0.2,1,I8>=0.1,0.7,I8>=0.05,0.4,TRUE,0),0))} -> 0 | L8: =IF($K8=0,0,$K8 / SUMIFS($K:$K,$A:$A,$A8,$D:$D,"Grenade")) -> 0
A9: {=IFERROR(INDEX(_xlfn._xlws.FILTER(Class_Players!A:A,Class_Players!B:B="Assault"),QUOTIENT(ROW()-ROW($A$2),7)+1),"")} -> Francko Escobar | B9: =_xlfn.XLOOKUP(A9,Class_Players!$A:$A,Class_Players!$B:$B,"") -> Assault | C9: {=INDEX(Lookups!$A$2:$A$8,MOD(ROW()-ROW($B$2),ROWS(Lookups!$A$2:$A$8))+1)} -> Assault Ladder | D9: =_xlfn.XLOOKUP(C9,Analysis_Gadgets!$C:$C,Analysis_Gadgets!$B:$B) -> Gadget | E9: 123 | F9: =_xlfn.XLOOKUP(A9,Class_Players!A:A,Class_Players!G:G) -> 388 | G9: =IF(F9=0,"",E9/F9) -> 0.31701031 | H9: =_xlfn.XLOOKUP(A9,Class_Players!A:A,Class_Players!F:F) -> 22167 | I9: =IF(H9=0,"",E9/H9) -> 0.0055487887 | J9: =IF(I9>=0.1,1,0) -> 0 | K9: {=IF(D9="Gadget",_xlfn.IFS(I9>=0.2,0.5,I9>=0.1,0.35,I9>=0.05,0.2,TRUE,0),IF(D9="Grenade",_xlfn.IFS(I9>=0.2,1,I9>=0.1,0.7,I9>=0.05,0.4,TRUE,0),0))} -> 0 | L9: =IF($K9=0,0,$K9 / SUMIFS($K:$K,$A:$A,$A9,$D:$D,"Gadget")) -> 0
A10: {=IFERROR(INDEX(_xlfn._xlws.FILTER(Class_Players!A:A,Class_Players!B:B="Assault"),QUOTIENT(ROW()-ROW($A$2),7)+1),"")} -> Francko Escobar | B10: =_xlfn.XLOOKUP(A10,Class_Players!$A:$A,Class_Players!$B:$B,"") -> Assault | C10: {=INDEX(Lookups!$A$2:$A$8,MOD(ROW()-ROW($B$2),ROWS(Lookups!$A$2:$A$8))+1)} -> X95 BRE (Breaching Projectile Launcher) | D10: =_xlfn.XLOOKUP(C10,Analysis_Gadgets!$C:$C,Analysis_Gadgets!$B:$B) -> Gadget | E10: 0 | F10: =_xlfn.XLOOKUP(A10,Class_Players!A:A,Class_Players!G:G) -> 388 | G10: =IF(F10=0,"",E10/F10) -> 0 | H10: =_xlfn.XLOOKUP(A10,Class_Players!A:A,Class_Players!F:F) -> 22167 | I10: =IF(H10=0,"",E10/H10) -> 0 | J10: =IF(I10>=0.1,1,0) -> 0 | K10: {=IF(D10="Gadget",_xlfn.IFS(I10>=0.2,0.5,I10>=0.1,0.35,I10>=0.05,0.2,TRUE,0),IF(D10="Grenade",_xlfn.IFS(I10>=0.2,1,I10>=0.1,0.7,I10>=0.05,0.4,TRUE,0),0))} -> 0 | L10: =IF($K10=0,0,$K10 / SUMIFS($K:$K,$A:$A,$A10,$D:$D,"Gadget")) -> 0
A11: {=IFERROR(INDEX(_xlfn._xlws.FILTER(Class_Players!A:A,Class_Players!B:B="Assault"),QUOTIENT(ROW()-ROW($A$2),7)+1),"")} -> Francko Escobar | B11: =_xlfn.XLOOKUP(A11,Class_Players!$A:$A,Class_Players!$B:$B,"") -> Assault | C11: {=INDEX(Lookups!$A$2:$A$8,MOD(ROW()-ROW($B$2),ROWS(Lookups!$A$2:$A$8))+1)} -> M320A1 HE (Grenade Launcher) | D11: =_xlfn.XLOOKUP(C11,Analysis_Gadgets!$C:$C,Analysis_Gadgets!$B:$B) -> Gadget | E11: 2529 | F11: =_xlfn.XLOOKUP(A11,Class_Players!A:A,Class_Players!G:G) -> 388 | G11: =IF(F11=0,"",E11/F11) -> 6.5180412 | H11: =_xlfn.XLOOKUP(A11,Class_Players!A:A,Class_Players!F:F) -> 22167 | I11: =IF(H11=0,"",E11/H11) -> 0.11408851 | J11: =IF(I11>=0.1,1,0) -> 1 | K11: {=IF(D11="Gadget",_xlfn.IFS(I11>=0.2,0.5,I11>=0.1,0.35,I11>=0.05,0.2,TRUE,0),IF(D11="Grenade",_xlfn.IFS(I11>=0.2,1,I11>=0.1,0.7,I11>=0.05,0.4,TRUE,0),0))} -> 0.35 | L11: =IF($K11=0,0,$K11 / SUMIFS($K:$K,$A:$A,$A11,$D:$D,"Gadget")) -> 1
A12: {=IFERROR(INDEX(_xlfn._xlws.FILTER(Class_Players!A:A,Class_Players!B:B="Assault"),QUOTIENT(ROW()-ROW($A$2),7)+1),"")} -> Francko Escobar | B12: =_xlfn.XLOOKUP(A12,Class_Players!$A:$A,Class_Players!$B:$B,"") -> Assault | C12: {=INDEX(Lookups!$A$2:$A$8,MOD(ROW()-ROW($B$2),ROWS(Lookups!$A$2:$A$8))+1)} -> M320A1 THRM (Incendiary Grenade Launcher) | D12: =_xlfn.XLOOKUP(C12,Analysis_Gadgets!$C:$C,Analysis_Gadgets!$B:$B) -> Gadget | E12: 252 | F12: =_xlfn.XLOOKUP(A12,Class_Players!A:A,Class_Players!G:G) -> 388 | G12: =IF(F12=0,"",E12/F12) -> 0.64948454 | H12: =_xlfn.XLOOKUP(A12,Class_Players!A:A,Class_Players!F:F) -> 22167 | I12: =IF(H12=0,"",E12/H12) -> 0.01136825 | J12: =IF(I12>=0.1,1,0) -> 0 | K12: {=IF(D12="Gadget",_xlfn.IFS(I12>=0.2,0.5,I12>=0.1,0.35,I12>=0.05,0.2,TRUE,0),IF(D12="Grenade",_xlfn.IFS(I12>=0.2,1,I12>=0.1,0.7,I12>=0.05,0.4,TRUE,0),0))} -> 0 | L12: =IF($K12=0,0,$K12 / SUMIFS($K:$K,$A:$A,$A12,$D:$D,"Gadget")) -> 0
A13: {=IFERROR(INDEX(_xlfn._xlws.FILTER(Class_Players!A:A,Class_Players!B:B="Assault"),QUOTIENT(ROW()-ROW($A$2),7)+1),"")} -> Francko Escobar | B13: =_xlfn.XLOOKUP(A13,Class_Players!$A:$A,Class_Players!$B:$B,"") -> Assault | C13: {=INDEX(Lookups!$A$2:$A$8,MOD(ROW()-ROW($B$2),ROWS(Lookups!$A$2:$A$8))+1)} -> QLINK (Deploy Beacon) | D13: =_xlfn.XLOOKUP(C13,Analysis_Gadgets!$C:$C,Analysis_Gadgets!$B:$B) -> Gadget | E13: 471 | F13: =_xlfn.XLOOKUP(A13,Class_Players!A:A,Class_Players!G:G) -> 388 | G13: =IF(F13=0,"",E13/F13) -> 1.2139175 | H13: =_xlfn.XLOOKUP(A13,Class_Players!A:A,Class_Players!F:F) -> 22167 | I13: =IF(H13=0,"",E13/H13) -> 0.021247801 | J13: =IF(I13>=0.1,1,0) -> 0 | K13: {=IF(D13="Gadget",_xlfn.IFS(I13>=0.2,0.5,I13>=0.1,0.35,I13>=0.05,0.2,TRUE,0),IF(D13="Grenade",_xlfn.IFS(I13>=0.2,1,I13>=0.1,0.7,I13>=0.05,0.4,TRUE,0),0))} -> 0 | L13: =IF($K13=0,0,$K13 / SUMIFS($K:$K,$A:$A,$A13,$D:$D,"Gadget")) -> 0
A14: {=IFERROR(INDEX(_xlfn._xlws.FILTER(Class_Players!A:A,Class_Players!B:B="Assault"),QUOTIENT(ROW()-ROW($A$2),7)+1),"")} -> Francko Escobar | B14: =_xlfn.XLOOKUP(A14,Class_Players!$A:$A,Class_Players!$B:$B,"") -> Assault | C14: {=INDEX(Lookups!$A$2:$A$8,MOD(ROW()-ROW($B$2),ROWS(Lookups!$A$2:$A$8))+1)} -> Stun Grenade | D14: =_xlfn.XLOOKUP(C14,Analysis_Gadgets!$C:$C,Analysis_Gadgets!$B:$B) -> Grenade | E14: 131 | F14: =_xlfn.XLOOKUP(A14,Class_Players!A:A,Class_Players!G:G) -> 388 | G14: =IF(F14=0,"",E14/F14) -> 0.33762887 | H14: =_xlfn.XLOOKUP(A14,Class_Players!A:A,Class_Players!F:F) -> 22167 | I14: =IF(H14=0,"",E14/H14) -> 0.0059096856 | J14: =IF(I14>=0.1,1,0) -> 0 | K14: {=IF(D14="Gadget",_xlfn.IFS(I14>=0.2,0.5,I14>=0.1,0.35,I14>=0.05,0.2,TRUE,0),IF(D14="Grenade",_xlfn.IFS(I14>=0.2,1,I14>=0.1,0.7,I14>=0.05,0.4,TRUE,0),0))} -> 0 | L14: =IF($K14=0,0,$K14 / SUMIFS($K:$K,$A:$A,$A14,$D:$D,"Grenade")) -> 0
A15: {=IFERROR(INDEX(_xlfn._xlws.FILTER(Class_Players!A:A,Class_Players!B:B="Assault"),QUOTIENT(ROW()-ROW($A$2),7)+1),"")} -> Francko Escobar | B15: =_xlfn.XLOOKUP(A15,Class_Players!$A:$A,Class_Players!$B:$B,"") -> Assault | C15: {=INDEX(Lookups!$A$2:$A$8,MOD(ROW()-ROW($B$2),ROWS(Lookups!$A$2:$A$8))+1)} -> Flash Grenade | D15: =_xlfn.XLOOKUP(C15,Analysis_Gadgets!$C:$C,Analysis_Gadgets!$B:$B) -> Grenade | E15: 99 | F15: =_xlfn.XLOOKUP(A15,Class_Players!A:A,Class_Players!G:G) -> 388 | G15: =IF(F15=0,"",E15/F15) -> 0.25515464 | H15: =_xlfn.XLOOKUP(A15,Class_Players!A:A,Class_Players!F:F) -> 22167 | I15: =IF(H15=0,"",E15/H15) -> 0.0044660983 | J15: =IF(I15>=0.1,1,0) -> 0 | K15: {=IF(D15="Gadget",_xlfn.IFS(I15>=0.2,0.5,I15>=0.1,0.35,I15>=0.05,0.2,TRUE,0),IF(D15="Grenade",_xlfn.IFS(I15>=0.2,1,I15>=0.1,0.7,I15>=0.05,0.4,TRUE,0),0))} -> 0 | L15: =IF($K15=0,0,$K15 / SUMIFS($K:$K,$A:$A,$A15,$D:$D,"Grenade")) -> 0
A16: {=IFERROR(INDEX(_xlfn._xlws.FILTER(Class_Players!A:A,Class_Players!B:B="Assault"),QUOTIENT(ROW()-ROW($A$2),7)+1),"")} -> CFGBOT | B16: =_xlfn.XLOOKUP(A16,Class_Players!$A:$A,Class_Players!$B:$B,"") -> Assault | C16: {=INDEX(Lookups!$A$2:$A$8,MOD(ROW()-ROW($B$2),ROWS(Lookups!$A$2:$A$8))+1)} -> Assault Ladder | D16: =_xlfn.XLOOKUP(C16,Analysis_Gadgets!$C:$C,Analysis_Gadgets!$B:$B) -> Gadget | E16: 2 | F16: =_xlfn.XLOOKUP(A16,Class_Players!A:A,Class_Players!G:G) -> 351 | G16: =IF(F16=0,"",E16/F16) -> 0.0056980057 | H16: =_xlfn.XLOOKUP(A16,Class_Players!$A:$A,Class_Players!$F:$F,"") -> 21125 | I16: =IF(H16=0,"",E16/H16) -> 9.4674556e-05 | J16: =IF(I16>=0.1,1,0) -> 0 | K16: {=IF(D16="Gadget",_xlfn.IFS(I16>=0.2,0.5,I16>=0.1,0.35,I16>=0.05,0.2,TRUE,0),IF(D16="Grenade",_xlfn.IFS(I16>=0.2,1,I16>=0.1,0.7,I16>=0.05,0.4,TRUE,0),0))} -> 0 | L16: =IF($K16=0,0,$K16 / SUMIFS($K:$K,$A:$A,$A16,$D:$D,"Gadget")) -> 0
A17: {=IFERROR(INDEX(_xlfn._xlws.FILTER(Class_Players!A:A,Class_Players!B:B="Assault"),QUOTIENT(ROW()-ROW($A$2),7)+1),"")} -> CFGBOT | B17: =_xlfn.XLOOKUP(A17,Class_Players!$A:$A,Class_Players!$B:$B,"") -> Assault | C17: {=INDEX(Lookups!$A$2:$A$8,MOD(ROW()-ROW($B$2),ROWS(Lookups!$A$2:$A$8))+1)} -> X95 BRE (Breaching Projectile Launcher) | D17: =_xlfn.XLOOKUP(C17,Analysis_Gadgets!$C:$C,Analysis_Gadgets!$B:$B) -> Gadget | E17: 0 | F17: =_xlfn.XLOOKUP(A17,Class_Players!A:A,Class_Players!G:G) -> 351 | G17: =IF(F17=0,"",E17/F17) -> 0 | H17: =_xlfn.XLOOKUP(A17,Class_Players!$A:$A,Class_Players!$F:$F,"") -> 21125 | I17: =IF(H17=0,"",E17/H17) -> 0 | J17: =IF(I17>=0.1,1,0) -> 0 | K17: {=IF(D17="Gadget",_xlfn.IFS(I17>=0.2,0.5,I17>=0.1,0.35,I17>=0.05,0.2,TRUE,0),IF(D17="Grenade",_xlfn.IFS(I17>=0.2,1,I17>=0.1,0.7,I17>=0.05,0.4,TRUE,0),0))} -> 0 | L17: =IF($K17=0,0,$K17 / SUMIFS($K:$K,$A:$A,$A17,$D:$D,"Gadget")) -> 0
A18: {=IFERROR(INDEX(_xlfn._xlws.FILTER(Class_Players!A:A,Class_Players!B:B="Assault"),QUOTIENT(ROW()-ROW($A$2),7)+1),"")} -> CFGBOT | B18: =_xlfn.XLOOKUP(A18,Class_Players!$A:$A,Class_Players!$B:$B,"") -> Assault | C18: {=INDEX(Lookups!$A$2:$A$8,MOD(ROW()-ROW($B$2),ROWS(Lookups!$A$2:$A$8))+1)} -> M320A1 HE (Grenade Launcher) | D18: =_xlfn.XLOOKUP(C18,Analysis_Gadgets!$C:$C,Analysis_Gadgets!$B:$B) -> Gadget | E18: 8810 | F18: =_xlfn.XLOOKUP(A18,Class_Players!A:A,Class_Players!G:G) -> 351 | G18: =IF(F18=0,"",E18/F18) -> 25.099715 | H18: =_xlfn.XLOOKUP(A18,Class_Players!$A:$A,Class_Players!$F:$F,"") -> 21125 | I18: =IF(H18=0,"",E18/H18) -> 0.41704142 | J18: =IF(I18>=0.1,1,0) -> 1 | K18: {=IF(D18="Gadget",_xlfn.IFS(I18>=0.2,0.5,I18>=0.1,0.35,I18>=0.05,0.2,TRUE,0),IF(D18="Grenade",_xlfn.IFS(I18>=0.2,1,I18>=0.1,0.7,I18>=0.05,0.4,TRUE,0),0))} -> 0.5 | L18: =IF($K18=0,0,$K18 / SUMIFS($K:$K,$A:$A,$A18,$D:$D,"Gadget")) -> 0.5
A19: {=IFERROR(INDEX(_xlfn._xlws.FILTER(Class_Players!A:A,Class_Players!B:B="Assault"),QUOTIENT(ROW()-ROW($A$2),7)+1),"")} -> CFGBOT | B19: =_xlfn.XLOOKUP(A19,Class_Players!$A:$A,Class_Players!$B:$B,"") -> Assault | C19: {=INDEX(Lookups!$A$2:$A$8,MOD(ROW()-ROW($B$2),ROWS(Lookups!$A$2:$A$8))+1)} -> M320A1 THRM (Incendiary Grenade Launcher) | D19: =_xlfn.XLOOKUP(C19,Analysis_Gadgets!$C:$C,Analysis_Gadgets!$B:$B) -> Gadget | E19: 193 | F19: =_xlfn.XLOOKUP(A19,Class_Players!A:A,Class_Players!G:G) -> 351 | G19: =IF(F19=0,"",E19/F19) -> 0.54985755 | H19: =_xlfn.XLOOKUP(A19,Class_Players!$A:$A,Class_Players!$F:$F,"") -> 21125 | I19: =IF(H19=0,"",E19/H19) -> 0.0091360947 | J19: =IF(I19>=0.1,1,0) -> 0 | K19: {=IF(D19="Gadget",_xlfn.IFS(I19>=0.2,0.5,I19>=0.1,0.35,I19>=0.05,0.2,TRUE,0),IF(D19="Grenade",_xlfn.IFS(I19>=0.2,1,I19>=0.1,0.7,I19>=0.05,0.4,TRUE,0),0))} -> 0 | L19: =IF($K19=0,0,$K19 / SUMIFS($K:$K,$A:$A,$A19,$D:$D,"Gadget")) -> 0
A20: {=IFERROR(INDEX(_xlfn._xlws.FILTER(Class_Players!A:A,Class_Players!B:B="Assault"),QUOTIENT(ROW()-ROW($A$2),7)+1),"")} -> CFGBOT | B20: =_xlfn.XLOOKUP(A20,Class_Players!$A:$A,Class_Players!$B:$B,"") -> Assault | C20: {=INDEX(Lookups!$A$2:$A$8,MOD(ROW()-ROW($B$2),ROWS(Lookups!$A$2:$A$8))+1)} -> QLINK (Deploy Beacon) | D20: =_xlfn.XLOOKUP(C20,Analysis_Gadgets!$C:$C,Analysis_Gadgets!$B:$B) -> Gadget | E20: 4829 | F20: =_xlfn.XLOOKUP(A20,Class_Players!A:A,Class_Players!G:G) -> 351 | G20: =IF(F20=0,"",E20/F20) -> 13.757835 | H20: =_xlfn.XLOOKUP(A20,Class_Players!$A:$A,Class_Players!$F:$F,"") -> 21125 | I20: =IF(H20=0,"",E20/H20) -> 0.22859172 | J20: =IF(I20>=0.1,1,0) -> 1 | K20: {=IF(D20="Gadget",_xlfn.IFS(I20>=0.2,0.5,I20>=0.1,0.35,I20>=0.05,0.2,TRUE,0),IF(D20="Grenade",_xlfn.IFS(I20>=0.2,1,I20>=0.1,0.7,I20>=0.05,0.4,TRUE,0),0))} -> 0.5 | L20: =IF($K20=0,0,$K20 / SUMIFS($K:$K,$A:$A,$A20,$D:$D,"Gadget")) -> 0.5
A21: {=IFERROR(INDEX(_xlfn._xlws.FILTER(Class_Players!A:A,Class_Players!B:B="Assault"),QUOTIENT(ROW()-ROW($A$2),7)+1),"")} -> CFGBOT | B21: =_xlfn.XLOOKUP(A21,Class_Players!$A:$A,Class_Players!$B:$B,"") -> Assault | C21: {=INDEX(Lookups!$A$2:$A$8,MOD(ROW()-ROW($B$2),ROWS(Lookups!$A$2:$A$8))+1)} -> Stun Grenade | D21: =_xlfn.XLOOKUP(C21,Analysis_Gadgets!$C:$C,Analysis_Gadgets!$B:$B) -> Grenade | E21: 39 | F21: =_xlfn.XLOOKUP(A21,Class_Players!A:A,Class_Players!G:G) -> 351 | G21: =IF(F21=0,"",E21/F21) -> 0.11111111 | H21: =_xlfn.XLOOKUP(A21,Class_Players!$A:$A,Class_Players!$F:$F,"") -> 21125 | I21: =IF(H21=0,"",E21/H21) -> 0.0018461538 | J21: =IF(I21>=0.1,1,0) -> 0 | K21: {=IF(D21="Gadget",_xlfn.IFS(I21>=0.2,0.5,I21>=0.1,0.35,I21>=0.05,0.2,TRUE,0),IF(D21="Grenade",_xlfn.IFS(I21>=0.2,1,I21>=0.1,0.7,I21>=0.05,0.4,TRUE,0),0))} -> 0 | L21: =IF($K21=0,0,$K21 / SUMIFS($K:$K,$A:$A,$A21,$D:$D,"Grenade")) -> 0
A22: {=IFERROR(INDEX(_xlfn._xlws.FILTER(Class_Players!A:A,Class_Players!B:B="Assault"),QUOTIENT(ROW()-ROW($A$2),7)+1),"")} -> CFGBOT | B22: =_xlfn.XLOOKUP(A22,Class_Players!$A:$A,Class_Players!$B:$B,"") -> Assault | C22: {=INDEX(Lookups!$A$2:$A$8,MOD(ROW()-ROW($B$2),ROWS(Lookups!$A$2:$A$8))+1)} -> Flash Grenade | D22: =_xlfn.XLOOKUP(C22,Analysis_Gadgets!$C:$C,Analysis_Gadgets!$B:$B) -> Grenade | E22: 61 | F22: =_xlfn.XLOOKUP(A22,Class_Players!A:A,Class_Players!G:G) -> 351 | G22: =IF(F22=0,"",E22/F22) -> 0.17378917 | H22: =_xlfn.XLOOKUP(A22,Class_Players!$A:$A,Class_Players!$F:$F,"") -> 21125 | I22: =IF(H22=0,"",E22/H22) -> 0.002887574 | J22: =IF(I22>=0.1,1,0) -> 0 | K22: {=IF(D22="Gadget",_xlfn.IFS(I22>=0.2,0.5,I22>=0.1,0.35,I22>=0.05,0.2,TRUE,0),IF(D22="Grenade",_xlfn.IFS(I22>=0.2,1,I22>=0.1,0.7,I22>=0.05,0.4,TRUE,0),0))} -> 0 | L22: =IF($K22=0,0,$K22 / SUMIFS($K:$K,$A:$A,$A22,$D:$D,"Grenade")) -> 0
A23: {=IFERROR(INDEX(_xlfn._xlws.FILTER(Class_Players!A:A,Class_Players!B:B="Assault"),QUOTIENT(ROW()-ROW($A$2),7)+1),"")} -> avengerhawk | B23: =_xlfn.XLOOKUP(A23,Class_Players!$A:$A,Class_Players!$B:$B,"") -> Assault | C23: {=INDEX(Lookups!$A$2:$A$8,MOD(ROW()-ROW($B$2),ROWS(Lookups!$A$2:$A$8))+1)} -> Assault Ladder | D23: =_xlfn.XLOOKUP(C23,Analysis_Gadgets!$C:$C,Analysis_Gadgets!$B:$B) -> Gadget | E23: 14 | F23: =_xlfn.XLOOKUP(A23,Class_Players!A:A,Class_Players!G:G) -> 258 | G23: =IF(F23=0,"",E23/F23) -> 0.054263566 | H23: =_xlfn.XLOOKUP(A23,Class_Players!$A:$A,Class_Players!$F:$F,"") -> 20105 | I23: =IF(H23=0,"",E23/H23) -> 0.00069634419 | J23: =IF(I23>=0.1,1,0) -> 0 | K23: {=IF(D23="Gadget",_xlfn.IFS(I23>=0.2,0.5,I23>=0.1,0.35,I23>=0.05,0.2,TRUE,0),IF(D23="Grenade",_xlfn.IFS(I23>=0.2,1,I23>=0.1,0.7,I23>=0.05,0.4,TRUE,0),0))} -> 0 | L23: =IF($K23=0,0,$K23 / SUMIFS($K:$K,$A:$A,$A23,$D:$D,"Gadget")) -> 0
A24: {=IFERROR(INDEX(_xlfn._xlws.FILTER(Class_Players!A:A,Class_Players!B:B="Assault"),QUOTIENT(ROW()-ROW($A$2),7)+1),"")} -> avengerhawk | B24: =_xlfn.XLOOKUP(A24,Class_Players!$A:$A,Class_Players!$B:$B,"") -> Assault | C24: {=INDEX(Lookups!$A$2:$A$8,MOD(ROW()-ROW($B$2),ROWS(Lookups!$A$2:$A$8))+1)} -> X95 BRE (Breaching Projectile Launcher) | D24: =_xlfn.XLOOKUP(C24,Analysis_Gadgets!$C:$C,Analysis_Gadgets!$B:$B) -> Gadget | E24: 65 | F24: =_xlfn.XLOOKUP(A24,Class_Players!A:A,Class_Players!G:G) -> 258 | G24: =IF(F24=0,"",E24/F24) -> 0.25193798 | H24: =_xlfn.XLOOKUP(A24,Class_Players!$A:$A,Class_Players!$F:$F,"") -> 20105 | I24: =IF(H24=0,"",E24/H24) -> 0.0032330266 | J24: =IF(I24>=0.1,1,0) -> 0 | K24: {=IF(D24="Gadget",_xlfn.IFS(I24>=0.2,0.5,I24>=0.1,0.35,I24>=0.05,0.2,TRUE,0),IF(D24="Grenade",_xlfn.IFS(I24>=0.2,1,I24>=0.1,0.7,I24>=0.05,0.4,TRUE,0),0))} -> 0 | L24: =IF($K24=0,0,$K24 / SUMIFS($K:$K,$A:$A,$A24,$D:$D,"Gadget")) -> 0
