Workbook

Sheet Player_Class_Profile
A1: Player_ID | B1: Leaderboard_Rank | C1: Deployments | D1: Assault_Time_Hour | E1: Engineer_Time_Hour | F1: Recon_Time_Hour | G1: Support_Time_Hour | H1: Total_Time_Hour | I1: Primary_Class | J1: Dominant-Class | K1: Dominance Percentage | L1: Snapshot_Date
A2: Stann83cz | B2: {=_xlfn.SEQUENCE(1000,1,7,10)} -> 7 | C2: 42845 | D2: 290 | E2: 42 | F2: 150 | G2: 65 | H2: =SUM(D2:G2) -> 547 | I2: {=_xlfn.LET(_xlpm.total,SUM(D2:G2),_xlpm.maxv,MAX(D2:G2),IF(_xlpm.total=0,"",IF(_xlpm.maxv/_xlpm.total<0.5,"Mixed-Class",_xlfn.IFS(_xlpm.maxv=D2,"Assault",_xlpm.maxv=E2,"Engineer",_xlpm.maxv=F2,"Recon",_xlpm.maxv=G2,"Support"))))} -> Assault | J2: =_xlfn.LET(_xlpm.total,SUM(D2:G2),IF(_xlpm.total=0,"",MAX(D2:G2)/_xlpm.total>=0.5)) -> TRUE | K2: =_xlfn.LET(_xlpm.total,SUM(D2:G2),IF(_xlpm.total=0,"",MAX(D2:G2)/_xlpm.total)) -> 0.53016453 | L2: 46046
A3: Sir Jekyll | B3: 17 | C3: 38077 | D3: 176 | E3: 216 | F3: 66 | G3: 130 | H3: =SUM(D3:G3) -> 588 | I3: {=_xlfn.LET(_xlpm.total,SUM(D3:G3),_xlpm.maxv,MAX(D3:G3),IF(_xlpm.total=0,"",IF(_xlpm.maxv/_xlpm.total<0.5,"Mixed-Class",_xlfn.IFS(_xlpm.maxv=D3,"Assault",_xlpm.maxv=E3,"Engineer",_xlpm.maxv=F3,"Recon",_xlpm.maxv=G3,"Support"))))} -> Mixed-Class | J3: =_xlfn.LET(_xlpm.total,SUM(D3:G3),IF(_xlpm.total=0,"",MAX(D3:G3)/_xlpm.total>=0.5)) -> FALSE | K3: =_xlfn.LET(_xlpm.total,SUM(D3:G3),IF(_xlpm.total=0,"",MAX(D3:G3)/_xlpm.total)) -> 0.36734694 | L3: 46046
A4: elkikisk | B4: 27 | C4: 36961 | D4: 326 | E4: 196 | F4: 41 | G4: 223 | H4: =SUM(D4:G4) -> 786 | I4: {=_xlfn.LET(_xlpm.total,SUM(D4:G4),_xlpm.maxv,MAX(D4:G4),IF(_xlpm.total=0,"",IF(_xlpm.maxv/_xlpm.total<0.5,"Mixed-Class",_xlfn.IFS(_xlpm.maxv=D4,"Assault",_xlpm.maxv=E4,"Engineer",_xlpm.maxv=F4,"Recon",_xlpm.maxv=G4,"Support"))))} -> Mixed-Class | J4: =_xlfn.LET(_xlpm.total,SUM(D4:G4),IF(_xlpm.total=0,"",MAX(D4:G4)/_xlpm.total>=0.5)) -> FALSE | K4: =_xlfn.LET(_xlpm.total,SUM(D4:G4),IF(_xlpm.total=0,"",MAX(D4:G4)/_xlpm.total)) -> 0.41475827 | L4: 46048
A5: HSBxEWIKKED | B5: 37 | C5: 35380 | D5: 1 | E5: 8 | F5: 105 | G5: 671 | H5: =SUM(D5:G5) -> 785 | I5: {=_xlfn.LET(_xlpm.total,SUM(D5:G5),_xlpm.maxv,MAX(D5:G5),IF(_xlpm.total=0,"",IF(_xlpm.maxv/_xlpm.total<0.5,"Mixed-Class",_xlfn.IFS(_xlpm.maxv=D5,"Assault",_xlpm.maxv=E5,"Engineer",_xlpm.maxv=F5,"Recon",_xlpm.maxv=G5,"Support"))))} -> Support | J5: =_xlfn.LET(_xlpm.total,SUM(D5:G5),IF(_xlpm.total=0,"",MAX(D5:G5)/_xlpm.total>=0.5)) -> TRUE | K5: =_xlfn.LET(_xlpm.total,SUM(D5:G5),IF(_xlpm.total=0,"",MAX(D5:G5)/_xlpm.total)) -> 0.85477707 | L5: 46048
A6: TheBishopDeath | B6: 47 | C6: 34290 | D6: 105 | E6: 390 | F6: 3 | G6: 37 | H6: =SUM(D6:G6) -> 535 | I6: {=_xlfn.LET(_xlpm.total,SUM(D6:G6),_xlpm.maxv,MAX(D6:G6),IF(_xlpm.total=0,"",IF(_xlpm.maxv/_xlpm.total<0.5,"Mixed-Class",_xlfn.IFS(_xlpm.maxv=D6,"Assault",_xlpm.maxv=E6,"Engineer",_xlpm.maxv=F6,"Recon",_xlpm.maxv=G6,"Support"))))} -> Engineer | J6: =_xlfn.LET(_xlpm.total,SUM(D6:G6),IF(_xlpm.total=0,"",MAX(D6:G6)/_xlpm.total>=0.5)) -> TRUE | K6: =_xlfn.LET(_xlpm.total,SUM(D6:G6),IF(_xlpm.total=0,"",MAX(D6:G6)/_xlpm.total)) -> 0.72897196 | L6: 46048
A7: AncientWizardGuy | B7: 57 | C7: 33277 | D7: 104 | E7: 156 | F7: 126 | G7: 211 | H7: =SUM(D7:G7) -> 597 | I7: {=_xlfn.LET(_xlpm.total,SUM(D7:G7),_xlpm.maxv,MAX(D7:G7),IF(_xlpm.total=0,"",IF(_xlpm.maxv/_xlpm.total<0.5,"Mixed-Class",_xlfn.IFS(_xlpm.maxv=D7,"Assault",_xlpm.maxv=E7,"Engineer",_xlpm.maxv=F7,"Recon",_xlpm.maxv=G7,"Support"))))} -> Mixed-Class | J7: =_xlfn.LET(_xlpm.total,SUM(D7:G7),IF(_xlpm.total=0,"",MAX(D7:G7)/_xlpm.total>=0.5)) -> FALSE | K7: =_xlfn.LET(_xlpm.total,SUM(D7:G7),IF(_xlpm.total=0,"",MAX(D7:G7)/_xlpm.total)) -> 0.35343384 | L7: 46048
A8: M5_eaglez | B8: 67 | C8: 32631 | D8: 233 | E8: 68 | F8: 62 | G8: 85 | H8: =SUM(D8:G8) -> 448 | I8: {=_xlfn.LET(_xlpm.total,SUM(D8:G8),_xlpm.maxv,MAX(D8:G8),IF(_xlpm.total=0,"",IF(_xlpm.maxv/_xlpm.total<0.5,"Mixed-Class",_xlfn.IFS(_xlpm.maxv=D8,"Assault",_xlpm.maxv=E8,"Engineer",_xlpm.maxv=F8,"Recon",_xlpm.maxv=G8,"Support"))))} -> Assault | J8: =_xlfn.LET(_xlpm.total,SUM(D8:G8),IF(_xlpm.total=0,"",MAX(D8:G8)/_xlpm.total>=0.5)) -> TRUE | K8: =_xlfn.LET(_xlpm.total,SUM(D8:G8),IF(_xlpm.total=0,"",MAX(D8:G8)/_xlpm.total)) -> 0.52008929 | L8: 46048
A9: Ragefast2311 | B9: 77 | C9: 32224 | D9: 10 | E9: 9 | F9: 12 | G9: 409 | H9: =SUM(D9:G9) -> 440 | I9: {=_xlfn.LET(_xlpm.total,SUM(D9:G9),_xlpm.maxv,MAX(D9:G9),IF(_xlpm.total=0,"",IF(_xlpm.maxv/_xlpm.total<0.5,"Mixed-Class",_xlfn.IFS(_xlpm.maxv=D9,"Assault",_xlpm.maxv=E9,"Engineer",_xlpm.maxv=F9,"Recon",_xlpm.maxv=G9,"Support"))))} -> Support | J9: =_xlfn.LET(_xlpm.total,SUM(D9:G9),IF(_xlpm.total=0,"",MAX(D9:G9)/_xlpm.total>=0.5)) -> TRUE | K9: =_xlfn.LET(_xlpm.total,SUM(D9:G9),IF(_xlpm.total=0,"",MAX(D9:G9)/_xlpm.total)) -> 0.92954545 | L9: 46048
A10: xCPC464x | B10: 87 | C10: 31404 | D10: 360 | E10: 35 | F10: 204 | G10: 56 | H10: =SUM(D10:G10) -> 655 | I10: {=_xlfn.LET(_xlpm.total,SUM(D10:G10),_xlpm.maxv,MAX(D10:G10),IF(_xlpm.total=0,"",IF(_xlpm.maxv/_xlpm.total<0.5,"Mixed-Class",_xlfn.IFS(_xlpm.maxv=D10,"Assault",_xlpm.maxv=E10,"Engineer",_xlpm.maxv=F10,"Recon",_xlpm.maxv=G10,"Support"))))} -> Assault | J10: =_xlfn.LET(_xlpm.total,SUM(D10:G10),IF(_xlpm.total=0,"",MAX(D10:G10)/_xlpm.total>=0.5)) -> TRUE | K10: =_xlfn.LET(_xlpm.total,SUM(D10:G10),IF(_xlpm.total=0,"",MAX(D10:G10)/_xlpm.total)) -> 0.54961832 | L10: 46048
A11: Benzo_ | B11: 97 | C11: 30772 | D11: 27 | E11: 152 | F11: 140 | G11: 203 | H11: =SUM(D11:G11) -> 522 | I11: {=_xlfn.LET(_xlpm.total,SUM(D11:G11),_xlpm.maxv,MAX(D11:G11),IF(_xlpm.total=0,"",IF(_xlpm.maxv/_xlpm.total<0.5,"Mixed-Class",_xlfn.IFS(_xlpm.maxv=D11,"Assault",_xlpm.maxv=E11,"Engineer",_xlpm.maxv=F11,"Recon",_xlpm.maxv=G11,"Support"))))} -> Mixed-Class | J11: =_xlfn.LET(_xlpm.total,SUM(D11:G11),IF(_xlpm.total=0,"",MAX(D11:G11)/_xlpm.total>=0.5)) -> FALSE | K11: =_xlfn.LET(_xlpm.total,SUM(D11:G11),IF(_xlpm.total=0,"",MAX(D11:G11)/_xlpm.total)) -> 0.38888889 | L11: 46048
A12: rgayregger | B12: 107 | C12: 31795 | D12: 252 | E12: 59 | F12: 30 | G12: 22 | H12: =SUM(D12:G12) -> 363 | I12: {=_xlfn.LET(_xlpm.total,SUM(D12:G12),_xlpm.maxv,MAX(D12:G12),IF(_xlpm.total=0,"",IF(_xlpm.maxv/_xlpm.total<0.5,"Mixed-Class",_xlfn.IFS(_xlpm.maxv=D12,"Assault",_xlpm.maxv=E12,"Engineer",_xlpm.maxv=F12,"Recon",_xlpm.maxv=G12,"Support"))))} -> Assault | J12: =_xlfn.LET(_xlpm.total,SUM(D12:G12),IF(_xlpm.total=0,"",MAX(D12:G12)/_xlpm.total>=0.5)) -> TRUE | K12: =_xlfn.LET(_xlpm.total,SUM(D12:G12),IF(_xlpm.total=0,"",MAX(D12:G12)/_xlpm.total)) -> 0.69421488 | L12: 46056
A13: dark_ken2284 | B13: 117 | C13: 31489 | D13: 234 | E13: 3 | F13: 104 | G13: 125 | H13: =SUM(D13:G13) -> 466 | I13: {=_xlfn.LET(_xlpm.total,SUM(D13:G13),_xlpm.maxv,MAX(D13:G13),IF(_xlpm.total=0,"",IF(_xlpm.maxv/_xlpm.total<0.5,"Mixed-Class",_xlfn.IFS(_xlpm.maxv=D13,"Assault",_xlpm.maxv=E13,"Engineer",_xlpm.maxv=F13,"Recon",_xlpm.maxv=G13,"Support"))))} -> Assault | J13: =_xlfn.LET(_xlpm.total,SUM(D13:G13),IF(_xlpm.total=0,"",MAX(D13:G13)/_xlpm.total>=0.5)) -> TRUE | K13: =_xlfn.LET(_xlpm.total,SUM(D13:G13),IF(_xlpm.total=0,"",MAX(D13:G13)/_xlpm.total)) -> 0.50214592 | L13: 46056
A14: Mosthated220 | B14: 127 | C14: 30755 | D14: 108 | E14: 86 | F14: 92 | G14: 71 | H14: =SUM(D14:G14) -> 357 | I14: {=_xlfn.LET(_xlpm.total,SUM(D14:G14),_xlpm.maxv,MAX(D14:G14),IF(_xlpm.total=0,"",IF(_xlpm.maxv/_xlpm.total<0.5,"Mixed-Class",_xlfn.IFS(_xlpm.maxv=D14,"Assault",_xlpm.maxv=E14,"Engineer",_xlpm.maxv=F14,"Recon",_xlpm.maxv=G14,"Support"))))} -> Mixed-Class | J14: =_xlfn.LET(_xlpm.total,SUM(D14:G14),IF(_xlpm.total=0,"",MAX(D14:G14)/_xlpm.total>=0.5)) -> FALSE | K14: =_xlfn.LET(_xlpm.total,SUM(D14:G14),IF(_xlpm.total=0,"",MAX(D14:G14)/_xlpm.total)) -> 0.30252101 | L14: 46056
... A37: FridaySV | B37: 357 | C37: 25922 | D37: 195 | E37: 102 | F37: 96 | G37: 75 | H37: =SUM(D37:G37) -> 468 | I37: {=_xlfn.LET(_xlpm.total,SUM(D37:G37),_xlpm.maxv,MAX(D37:G37),IF(_xlpm.total=0,"",IF(_xlpm.maxv/_xlpm.total<0.5,"Mixed-Class",_xlfn.IFS(_xlpm.maxv=D37,"Assault",_xlpm.maxv=E37,"Engineer",_xlpm.maxv=F37,"Recon",_xlpm.maxv=G37,"Support"))))} -> Mixed-Class | J37: =_xlfn.LET(_xlpm.total,SUM(D37:G37),IF(_xlpm.total=0,"",MAX(D37:G37)/_xlpm.total>=0.5)) -> FALSE | K37: =_xlfn.LET(_xlpm.total,SUM(D37:G37),IF(_xlpm.total=0,"",MAX(D37:G37)/_xlpm.total)) -> 0.41666667 | L37: 46057
A38: Polishman22 | B38: 367 | C38: 25774 | D38: 181 | E38: 137 | F38: 75 | G38: 73 | H38: =SUM(D39:G39) -> 569 | I38: {=_xlfn.LET(_xlpm.total,SUM(D38:G38),_xlpm.maxv,MAX(D38:G38),IF(_xlpm.total=0,"",IF(_xlpm.maxv/_xlpm.total<0.5,"Mixed-Class",_xlfn.IFS(_xlpm.maxv=D38,"Assault",_xlpm.maxv=E38,"Engineer",_xlpm.maxv=F38,"Recon",_xlpm.maxv=G38,"Support"))))} -> Mixed-Class | J38: =_xlfn.LET(_xlpm.total,SUM(D38:G38),IF(_xlpm.total=0,"",MAX(D38:G38)/_xlpm.total>=0.5)) -> FALSE | K38: =_xlfn.LET(_xlpm.total,SUM(D38:G38),IF(_xlpm.total=0,"",MAX(D38:G38)/_xlpm.total)) -> 0.38841202 | L38: 46057
A39: SuperPikasso | B39: 377 | C39: 25676 | D39: 105 | E39: 173 | F39: 121 | G39: 170 | H39: =SUM(D39:G39) -> 569 | I39: {=_xlfn.LET(_xlpm.total,SUM(D39:G39),_xlpm.maxv,MAX(D39:G39),IF(_xlpm.total=0,"",IF(_xlpm.maxv/_xlpm.total<0.5,"Mixed-Class",_xlfn.IFS(_xlpm.maxv=D39,"Assault",_xlpm.maxv=E39,"Engineer",_xlpm.maxv=F39,"Recon",_xlpm.maxv=G39,"Support"))))} -> Mixed-Class | J39: =_xlfn.LET(_xlpm.total,SUM(D39:G39),IF(_xlpm.total=0,"",MAX(D39:G39)/_xlpm.total>=0.5)) -> FALSE | K39: =_xlfn.LET(_xlpm.total,SUM(D39:G39),IF(_xlpm.total=0,"",MAX(D39:G39)/_xlpm.total)) -> 0.30404218 | L39: 46057
A40: Olegich_999 | B40: 387 | C40: 25566 | D40: 143 | E40: 172 | F40: 78 | G40: 118 | H40: =SUM(D40:G40) -> 511 | I40: {=_xlfn.LET(_xlpm.total,SUM(D40:G40),_xlpm.maxv,MAX(D40:G40),IF(_xlpm.total=0,"",IF(_xlpm.maxv/_xlpm.total<0.5,"Mixed-Class",_xlfn.IFS(_xlpm.maxv=D40,"Assault",_xlpm.maxv=E40,"Engineer",_xlpm.maxv=F40,"Recon",_xlpm.maxv=G40,"Support"))))} -> Mixed-Class | J40: =_xlfn.LET(_xlpm.total,SUM(D40:G40),IF(_xlpm.total=0,"",MAX(D40:G40)/_xlpm.total>=0.5)) -> FALSE | K40: =_xlfn.LET(_xlpm.total,SUM(D40:G40),IF(_xlpm.total=0,"",MAX(D40:G40)/_xlpm.total)) -> 0.33659491 | L40: 46057
A41: VITARTA | B41: 397 | C41: 25485 | D41: 13 | E41: 25 | F41: 349 | G41: 24 | H41: =SUM(D41:G41) -> 411 | I41: {=_xlfn.LET(_xlpm.total,SUM(D41:G41),_xlpm.maxv,MAX(D41:G41),IF(_xlpm.total=0,"",IF(_xlpm.maxv/_xlpm.total<0.5,"Mixed-Class",_xlfn.IFS(_xlpm.maxv=D41,"Assault",_xlpm.maxv=E41,"Engineer",_xlpm.maxv=F41,"Recon",_xlpm.maxv=G41,"Support"))))} -> Recon | J41: =_xlfn.LET(_xlpm.total,SUM(D41:G41),IF(_xlpm.total=0,"",MAX(D41:G41)/_xlpm.total>=0.5)) -> TRUE | K41: =_xlfn.LET(_xlpm.total,SUM(D41:G41),IF(_xlpm.total=0,"",MAX(D41:G41)/_xlpm.total)) -> 0.84914842 | L41: 46057
A42: Puddy | B42: 407 | C42: 25413 | D42: 108 | E42: 173 | F42: 26 | G42: 69 | H42: =SUM(D42:G42) -> 376 | I42: {=_xlfn.LET(_xlpm.total,SUM(D42:G42),_xlpm.maxv,MAX(D42:G42),IF(_xlpm.total=0,"",IF(_xlpm.maxv/_xlpm.total<0.5,"Mixed-Class",_xlfn.IFS(_xlpm.maxv=D42,"Assault",_xlpm.maxv=E42,"Engineer",_xlpm.maxv=F42,"Recon",_xlpm.maxv=G42,"Support"))))} -> Mixed-Class | J42: =_xlfn.LET(_xlpm.total,SUM(D42:G42),IF(_xlpm.total=0,"",MAX(D42:G42)/_xlpm.total>=0.5)) -> FALSE | K42: =_xlfn.LET(_xlpm.total,SUM(D42:G42),IF(_xlpm.total=0,"",MAX(D42:G42)/_xlpm.total)) -> 0.46010638 | L42: 46057
A43: LtFrankDrebiin | B43: 417 | C43: 25303 | D43: 92 | E43: 129 | F43: 45 | G43: 159 | H43: =SUM(D43:G43) -> 425 | I43: {=_xlfn.LET(_xlpm.total,SUM(D43:G43),_xlpm.maxv,MAX(D43:G43),IF(_xlpm.total=0,"",IF(_xlpm.maxv/_xlpm.total<0.5,"Mixed-Class",_xlfn.IFS(_xlpm.maxv=D43,"Assault",_xlpm.maxv=E43,"Engineer",_xlpm.maxv=F43,"Recon",_xlpm.maxv=G43,"Support"))))} -> Mixed-Class | J43: =_xlfn.LET(_xlpm.total,SUM(D43:G43),IF(_xlpm.total=0,"",MAX(D43:G43)/_xlpm.total>=0.5)) -> FALSE | K43: =_xlfn.LET(_xlpm.total,SUM(D43:G43),IF(_xlpm.total=0,"",MAX(D43:G43)/_xlpm.total)) -> 0.37411765 | L43: 46057
A44: Ambrokinarrow | B44: 427 | C44: 25192 | D44: 14 | E44: 15 | F44: 28 | G44: 177 | H44: =SUM(D44:G44) -> 234 | I44: {=_xlfn.LET(_xlpm.total,SUM(D44:G44),_xlpm.maxv,MAX(D44:G44),IF(_xlpm.total=0,"",IF(_xlpm.maxv/_xlpm.total<0.5,"Mixed-Class",_xlfn.IFS(_xlpm.maxv=D44,"Assault",_xlpm.maxv=E44,"Engineer",_xlpm.maxv=F44,"Recon",_xlpm.maxv=G44,"Support"))))} -> Support | J44: =_xlfn.LET(_xlpm.total,SUM(D44:G44),IF(_xlpm.total=0,"",MAX(D44:G44)/_xlpm.total>=0.5)) -> TRUE | K44: =_xlfn.LET(_xlpm.total,SUM(D44:G44),IF(_xlpm.total=0,"",MAX(D44:G44)/_xlpm.total)) -> 0.75641026 | L44: 46057
A45: heroic_her0ooo | B45: 437 | C45: 25142 | D45: 55 | E45: 41 | F45: 110 | G45: 274 | H45: =SUM(D45:G45) -> 480 | I45: {=_xlfn.LET(_xlpm.total,SUM(D45:G45),_xlpm.maxv,MAX(D45:G45),IF(_xlpm.total=0,"",IF(_xlpm.maxv/_xlpm.total<0.5,"Mixed-Class",_xlfn.IFS(_xlpm.maxv=D45,"Assault",_xlpm.maxv=E45,"Engineer",_xlpm.maxv=F45,"Recon",_xlpm.maxv=G45,"Support"))))} -> Support | J45: =_xlfn.LET(_xlpm.total,SUM(D45:G45),IF(_xlpm.total=0,"",MAX(D45:G45)/_xlpm.total>=0.5)) -> TRUE | K45: =_xlfn.LET(_xlpm.total,SUM(D45:G45),IF(_xlpm.total=0,"",MAX(D45:G45)/_xlpm.total)) -> 0.57083333 | L45: 46057
A46: MICHEL_Bagual | B46: 447 | C46: 25048 | D46: 184 | E46: 76 | F46: 35 | G46: 169 | H46: =SUM(D46:G46) -> 464 | I46: {=_xlfn.LET(_xlpm.total,SUM(D46:G46),_xlpm.maxv,MAX(D46:G46),IF(_xlpm.total=0,"",IF(_xlpm.maxv/_xlpm.total<0.5,"Mixed-Class",_xlfn.IFS(_xlpm.maxv=D46,"Assault",_xlpm.maxv=E46,"Engineer",_xlpm.maxv=F46,"Recon",_xlpm.maxv=G46,"Support"))))} -> Mixed-Class | J46: =_xlfn.LET(_xlpm.total,SUM(D46:G46),IF(_xlpm.total=0,"",MAX(D46:G46)/_xlpm.total>=0.5)) -> FALSE | K46: =_xlfn.LET(_xlpm.total,SUM(D46:G46),IF(_xlpm.total=0,"",MAX(D46:G46)/_xlpm.total)) -> 0.39655172 | L46: 46057
A47: DenisRezh | B47: 457 | C47: 24969 | D47: 210 | E47: 198 | F47: 163 | G47: 212 | H47: =SUM(D47:G47) -> 783 | I47: {=_xlfn.LET(_xlpm.total,SUM(D47:G47),_xlpm.maxv,MAX(D47:G47),IF(_xlpm.total=0,"",IF(_xlpm.maxv/_xlpm.total<0.5,"Mixed-Class",_xlfn.IFS(_xlpm.maxv=D47,"Assault",_xlpm.maxv=E47,"Engineer",_xlpm.maxv=F47,"Recon",_xlpm.maxv=G47,"Support"))))} -> Mixed-Class | J47: =_xlfn.LET(_xlpm.total,SUM(D47:G47),IF(_xlpm.total=0,"",MAX(D47:G47)/_xlpm.total>=0.5)) -> FALSE | K47: =_xlfn.LET(_xlpm.total,SUM(D47:G47),IF(_xlpm.total=0,"",MAX(D47:G47)/_xlpm.total)) -> 0.27075351 | L47: 46057
A48: 清蒸哈基米 | B48: 467 | C48: 24791 | D48: 237 | E48: 4.5 | F48: 0.5 | G48: 52 | H48: =SUM(D48:G48) -> 294 | I48: {=_xlfn.LET(_xlpm.total,SUM(D48:G48),_xlpm.maxv,MAX(D48:G48),IF(_xlpm.total=0,"",IF(_xlpm.maxv/_xlpm.total<0.5,"Mixed-Class",_xlfn.IFS(_xlpm.maxv=D48,"Assault",_xlpm.maxv=E48,"Engineer",_xlpm.maxv=F48,"Recon",_xlpm.maxv=G48,"Support"))))} -> Assault | J48: =_xlfn.LET(_xlpm.total,SUM(D48:G48),IF(_xlpm.total=0,"",MAX(D48:G48)/_xlpm.total>=0.5)) -> TRUE | K48: =_xlfn.LET(_xlpm.total,SUM(D48:G48),IF(_xlpm.total=0,"",MAX(D48:G48)/_xlpm.total)) -> 0.80612245 | L48: 46057
A49: deesmoke180 | B49: 477 | C49: 24684 | D49: 109 | E49: 93 | F49: 114 | G49: 86 | H49: =SUM(D49:G49) -> 402 | I49: {=_xlfn.LET(_xlpm.total,SUM(D49:G49),_xlpm.maxv,MAX(D49:G49),IF(_xlpm.total=0,"",IF(_xlpm.maxv/_xlpm.total<0.5,"Mixed-Class",_xlfn.IFS(_xlpm.maxv=D49,"Assault",_xlpm.maxv=E49,"Engineer",_xlpm.maxv=F49,"Recon",_xlpm.maxv=G49,"Support"))))} -> Mixed-Class | J49: =_xlfn.LET(_xlpm.total,SUM(D49:G49),IF(_xlpm.total=0,"",MAX(D49:G49)/_xlpm.total>=0.5)) -> FALSE | K49: =_xlfn.LET(_xlpm.total,SUM(D49:G49),IF(_xlpm.total=0,"",MAX(D49:G49)/_xlpm.total)) -> 0.28358209 | L49: 46057
A50: Comatose615 | B50: 487 | C50: 24622 | D50: 138 | E50: 481 | F50: 77 | G50: 46 | H50: =SUM(D50:G50) -> 742 | I50: {=_xlfn.LET(_xlpm.total,SUM(D50:G50),_xlpm.maxv,MAX(D50:G50),IF(_xlpm.total=0,"",IF(_xlpm.maxv/_xlpm.total<0.5,"Mixed-Class",_xlfn.IFS(_xlpm.maxv=D50,"Assault",_xlpm.maxv=E50,"Engineer",_xlpm.maxv=F50,"Recon",_xlpm.maxv=G50,"Support"))))} -> Engineer | J50: =_xlfn.LET(_xlpm.total,SUM(D50:G50),IF(_xlpm.total=0,"",MAX(D50:G50)/_xlpm.total>=0.5)) -> TRUE | K50: =_xlfn.LET(_xlpm.total,SUM(D50:G50),IF(_xlpm.total=0,"",MAX(D50:G50)/_xlpm.total)) -> 0.64824798 | L50: 46057
... A101: tc_likeman01 | B101: 997 | C101: 21512 | D101: 34 | E101: 134 | F101: 83 | G101: 206 | H101: =SUM(D101:G101) -> 457 | I101: {=_xlfn.LET(_xlpm.total,SUM(D101:G101),_xlpm.maxv,MAX(D101:G101),IF(_xlpm.total=0,"",IF(_xlpm.maxv/_xlpm.total<0.5,"Mixed-Class",_xlfn.IFS(_xlpm.maxv=D101,"Assault",_xlpm.maxv=E101,"Engineer",_xlpm.maxv=F101,"Recon",_xlpm.maxv=G101,"Support"))))} -> Mixed-Class | J101: =_xlfn.LET(_xlpm.total,SUM(D101:G101),IF(_xlpm.total=0,"",MAX(D101:G101)/_xlpm.total>=0.5)) -> FALSE | K101: =_xlfn.LET(_xlpm.total,SUM(D101:G101),IF(_xlpm.total=0,"",MAX(D101:G101)/_xlpm.total)) -> 0.45076586 | L101: 46059
B102: 1007 | H102: =SUM(D102:G102) -> 0 | I102: {=_xlfn.LET(_xlpm.total,SUM(D102:G102),_xlpm.maxv,MAX(D102:G102),IF(_xlpm.total=0,"",IF(_xlpm.maxv/_xlpm.total<0.5,"Mixed-Class",_xlfn.IFS(_xlpm.maxv=D102,"Assault",_xlpm.maxv=E102,"Engineer",_xlpm.maxv=F102,"Recon",_xlpm.maxv=G102,"Support"))))} | J102: =_xlfn.LET(_xlpm.total,SUM(D102:G102),IF(_xlpm.total=0,"",MAX(D102:G102)/_xlpm.total>=0.5)) | K102: =_xlfn.LET(_xlpm.total,SUM(D102:G102),IF(_xlpm.total=0,"",MAX(D102:G102)/_xlpm.total))
B103: 1017 | H103: =SUM(D103:G103) -> 0 | I103: {=_xlfn.LET(_xlpm.total,SUM(D103:G103),_xlpm.maxv,MAX(D103:G103),IF(_xlpm.total=0,"",IF(_xlpm.maxv/_xlpm.total<0.5,"Mixed-Class",_xlfn.IFS(_xlpm.maxv=D103,"Assault",_xlpm.maxv=E103,"Engineer",_xlpm.maxv=F103,"Recon",_xlpm.maxv=G103,"Support"))))} | J103: =_xlfn.LET(_xlpm.total,SUM(D103:G103),IF(_xlpm.total=0,"",MAX(D103:G103)/_xlpm.total>=0.5)) | K103: =_xlfn.LET(_xlpm.total,SUM(D103:G103),IF(_xlpm.total=0,"",MAX(D103:G103)/_xlpm.total))
B104: 1027 | H104: =SUM(D104:G104) -> 0 | I104: {=_xlfn.LET(_xlpm.total,SUM(D104:G104),_xlpm.maxv,MAX(D104:G104),IF(_xlpm.total=0,"",IF(_xlpm.maxv/_xlpm.total<0.5,"Mixed-Class",_xlfn.IFS(_xlpm.maxv=D104,"Assault",_xlpm.maxv=E104,"Engineer",_xlpm.maxv=F104,"Recon",_xlpm.maxv=G104,"Support"))))} | J104: =_xlfn.LET(_xlpm.total,SUM(D104:G104),IF(_xlpm.total=0,"",MAX(D104:G104)/_xlpm.total>=0.5)) | K104: =_xlfn.LET(_xlpm.total,SUM(D104:G104),IF(_xlpm.total=0,"",MAX(D104:G104)/_xlpm.total))
B105: 1037 | H105: =SUM(D105:G105) -> 0 | I105: {=_xlfn.LET(_xlpm.total,SUM(D105:G105),_xlpm.maxv,MAX(D105:G105),IF(_xlpm.total=0,"",IF(_xlpm.maxv/_xlpm.total<0.5,"Mixed-Class",_xlfn.IFS(_xlpm.maxv=D105,"Assault",_xlpm.maxv=E105,"Engineer",_xlpm.maxv=F105,"Recon",_xlpm.maxv=G105,"Support"))))} | J105: =_xlfn.LET(_xlpm.total,SUM(D105:G105),IF(_xlpm.total=0,"",MAX(D105:G105)/_xlpm.total>=0.5)) | K105: =_xlfn.LET(_xlpm.total,SUM(D105:G105),IF(_xlpm.total=0,"",MAX(D105:G105)/_xlpm.total))
B106: 1047 | H106: =SUM(D106:G106) -> 0 | I106: {=_xlfn.LET(_xlpm.total,SUM(D106:G106),_xlpm.maxv,MAX(D106:G106),IF(_xlpm.total=0,"",IF(_xlpm.maxv/_xlpm.total<0.5,"Mixed-Class",_xlfn.IFS(_xlpm.maxv=D106,"Assault",_xlpm.maxv=E106,"Engineer",_xlpm.maxv=F106,"Recon",_xlpm.maxv=G106,"Support"))))} | J106: =_xlfn.LET(_xlpm.total,SUM(D106:G106),IF(_xlpm.total=0,"",MAX(D106:G106)/_xlpm.total>=0.5)) | K106: =_xlfn.LET(_xlpm.total,SUM(D106:G106),IF(_xlpm.total=0,"",MAX(D106:G106)/_xlpm.total))
B107: 1057 | H107: =SUM(D107:G107) -> 0 | I107: {=_xlfn.LET(_xlpm.total,SUM(D107:G107),_xlpm.maxv,MAX(D107:G107),IF(_xlpm.total=0,"",IF(_xlpm.maxv/_xlpm.total<0.5,"Mixed-Class",_xlfn.IFS(_xlpm.maxv=D107,"Assault",_xlpm.maxv=E107,"Engineer",_xlpm.maxv=F107,"Recon",_xlpm.maxv=G107,"Support"))))} | J107: =_xlfn.LET(_xlpm.total,SUM(D107:G107),IF(_xlpm.total=0,"",MAX(D107:G107)/_xlpm.total>=0.5)) | K107: =_xlfn.LET(_xlpm.total,SUM(D107:G107),IF(_xlpm.total=0,"",MAX(D107:G107)/_xlpm.total))
B108: 1067 | H108: =SUM(D108:G108) -> 0 | I108: {=_xlfn.LET(_xlpm.total,SUM(D108:G108),_xlpm.maxv,MAX(D108:G108),IF(_xlpm.total=0,"",IF(_xlpm.maxv/_xlpm.total<0.5,"Mixed-Class",_xlfn.IFS(_xlpm.maxv=D108,"Assault",_xlpm.maxv=E108,"Engineer",_xlpm.maxv=F108,"Recon",_xlpm.maxv=G108,"Support"))))} | J108: =_xlfn.LET(_xlpm.total,SUM(D108:G108),IF(_xlpm.total=0,"",MAX(D108:G108)/_xlpm.total>=0.5)) | K108: =_xlfn.LET(_xlpm.total,SUM(D108:G108),IF(_xlpm.total=0,"",MAX(D108:G108)/_xlpm.total))
B109: 1077 | H109: =SUM(D109:G109) -> 0 | I109: {=_xlfn.LET(_xlpm.total,SUM(D109:G109),_xlpm.maxv,MAX(D109:G109),IF(_xlpm.total=0,"",IF(_xlpm.maxv/_xlpm.total<0.5,"Mixed-Class",_xlfn.IFS(_xlpm.maxv=D109,"Assault",_xlpm.maxv=E109,"Engineer",_xlpm.maxv=F109,"Recon",_xlpm.maxv=G109,"Support"))))} | J109: =_xlfn.LET(_xlpm.total,SUM(D109:G109),IF(_xlpm.total=0,"",MAX(D109:G109)/_xlpm.total>=0.5)) | K109: =_xlfn.LET(_xlpm.total,SUM(D109:G109),IF(_xlpm.total=0,"",MAX(D109:G109)/_xlpm.total))
B110: 1087 | H110: =SUM(D110:G110) -> 0 | I110: {=_xlfn.LET(_xlpm.total,SUM(D110:G110),_xlpm.maxv,MAX(D110:G110),IF(_xlpm.total=0,"",IF(_xlpm.maxv/_xlpm.total<0.5,"Mixed-Class",_xlfn.IFS(_xlpm.maxv=D110,"Assault",_xlpm.maxv=E110,"Engineer",_xlpm.maxv=F110,"Recon",_xlpm.maxv=G110,"Support"))))} | J110: =_xlfn.LET(_xlpm.total,SUM(D110:G110),IF(_xlpm.total=0,"",MAX(D110:G110)/_xlpm.total>=0.5)) | K110: =_xlfn.LET(_xlpm.total,SUM(D110:G110),IF(_xlpm.total=0,"",MAX(D110:G110)/_xlpm.total))
B111: 1097 | H111: =SUM(D111:G111) -> 0 | I111: {=_xlfn.LET(_xlpm.total,SUM(D111:G111),_xlpm.maxv,MAX(D111:G111),IF(_xlpm.total=0,"",IF(_xlpm.maxv/_xlpm.total<0.5,"Mixed-Class",_xlfn.IFS(_xlpm.maxv=D111,"Assault",_xlpm.maxv=E111,"Engineer",_xlpm.maxv=F111,"Recon",_xlpm.maxv=G111,"Support"))))} | J111: =_xlfn.LET(_xlpm.total,SUM(D111:G111),IF(_xlpm.total=0,"",MAX(D111:G111)/_xlpm.total>=0.5)) | K111: =_xlfn.LET(_xlpm.total,SUM(D111:G111),IF(_xlpm.total=0,"",MAX(D111:G111)/_xlpm.total))
B112: 1107 | H112: =SUM(D112:G112) -> 0 | I112: {=_xlfn.LET(_xlpm.total,SUM(D112:G112),_xlpm.maxv,MAX(D112:G112),IF(_xlpm.total=0,"",IF(_xlpm.maxv/_xlpm.total<0.5,"Mixed-Class",_xlfn.IFS(_xlpm.maxv=D112,"Assault",_xlpm.maxv=E112,"Engineer",_xlpm.maxv=F112,"Recon",_xlpm.maxv=G112,"Support"))))} | J112: =_xlfn.LET(_xlpm.total,SUM(D112:G112),IF(_xlpm.total=0,"",MAX(D112:G112)/_xlpm.total>=0.5)) | K112: =_xlfn.LET(_xlpm.total,SUM(D112:G112),IF(_xlpm.total=0,"",MAX(D112:G112)/_xlpm.total))
...

Sheet Player_Mode_Profile
A1: Player_ID | B1: Leaderboard_Rank | C1: Conquest_Hours | D1: Escalation_Hours | E1: Breakthrough_Hours | F1: Rush_Hours | G1: TDM | H1: SDM | I1: Strikepoint | J1: Gauntlet | K1: Domination | L1: KotH | M1: Sabotage | N1: BR Quads | O1: BR Duos | P1: Vehicle_Time_Hour | Q1: Mixed_Time_Hour | R1: Infantry_Time_Hour | S1: Battle_Royale_Hour | T1: Total_Mode_Hours | U1: Map_Tendency
A2: =Player_Class_Profile!A2 -> Stann83cz | B2: {=_xlfn.SEQUENCE(1000,1,7,10)} -> 7 | C2: 205 | D2: 19 | E2: 101 | F2: 4.5 | G2: 8 | H2: 19 | I2: 0.5 | J2: 1 | K2: 52 | L2: 228 | M2: 17 | N2: 8 | O2: 3 | P2: =SUM(Player_Mode_Profile!C2:D2) -> 224 | Q2: =SUM(Player_Mode_Profile!E2:F2) -> 105.5 | R2: =SUM(Player_Mode_Profile!G2:M2) -> 325.5 | S2: =SUM(Player_Mode_Profile!N2:O2) -> 11 | T2: =SUM(P2:S2) -> 666 | U2: =IF(SUM(P2:S2)=0,"",IF(S2/SUM(P2:S2)>=0.5,"Battle Royale",IF(R2/SUM(P2:R2)>=0.6,"Infantry-Heavy",IF((P2+0.7*Q2)/SUM(P2:R2)>=0.65,"Vehicle-Heavy","Mixed")))) -> Mixed
A3: =Player_Class_Profile!A3 -> Sir Jekyll | B3: 17 | C3: 343 | D3: 6 | E3: 103 | F3: 3.5 | G3: 4.5 | H3: 85 | I3: 0 | J3: 8 | K3: 2 | L3: 1 | M3: 1 | N3: 16 | O3: 108 | P3: =SUM(Player_Mode_Profile!C3:D3) -> 349 | Q3: =SUM(Player_Mode_Profile!E3:F3) -> 106.5 | R3: =SUM(Player_Mode_Profile!G3:M3) -> 101.5 | S3: =SUM(Player_Mode_Profile!N3:O3) -> 124 | T3: =SUM(P3:S3) -> 681 | U3: =IF(SUM(P3:S3)=0,"",IF(S3/SUM(P3:S3)>=0.5,"Battle Royale",IF(R3/SUM(P3:R3)>=0.6,"Infantry-Heavy",IF((P3+0.7*Q3)/SUM(P3:R3)>=0.65,"Vehicle-Heavy","Mixed")))) -> Vehicle-Heavy
A4: =Player_Class_Profile!A4 -> elkikisk | B4: 27 | C4: 201 | D4: 600 | E4: 33 | F4: 89 | G4: 0.75 | H4: 4 | I4: 0.25 | J4: 3 | K4: 4 | L4: 1 | M4: 1 | N4: 0.25 | O4: 0.1 | P4: =SUM(Player_Mode_Profile!C4:D4) -> 801 | Q4: =SUM(Player_Mode_Profile!E4:F4) -> 122 | R4: =SUM(Player_Mode_Profile!G4:M4) -> 14 | S4: =SUM(Player_Mode_Profile!N4:O4) -> 0.35 | T4: =SUM(P4:S4) -> 937.35 | U4: =IF(SUM(P4:S4)=0,"",IF(S4/SUM(P4:S4)>=0.5,"Battle Royale",IF(R4/SUM(P4:R4)>=0.6,"Infantry-Heavy",IF((P4+0.7*Q4)/SUM(P4:R4)>=0.65,"Vehicle-Heavy","Mixed")))) -> Vehicle-Heavy
A5: =Player_Class_Profile!A5 -> HSBxEWIKKED | B5: 37 | C5: 91 | D5: 9.25 | E5: 84 | F5: 9 | G5: 245 | H5: 105 | I5: 49 | J5: 7 | K5: 50 | L5: 95 | M5: 50 | N5: 27 | O5: 88 | P5: =SUM(Player_Mode_Profile!C5:D5) -> 100.25 | Q5: =SUM(Player_Mode_Profile!E5:F5) -> 93 | R5: =SUM(Player_Mode_Profile!G5:M5) -> 601 | S5: =SUM(Player_Mode_Profile!N5:O5) -> 115 | T5: =SUM(P5:S5) -> 909.25 | U5: =IF(SUM(P5:S5)=0,"",IF(S5/SUM(P5:S5)>=0.5,"Battle Royale",IF(R5/SUM(P5:R5)>=0.6,"Infantry-Heavy",IF((P5+0.7*Q5)/SUM(P5:R5)>=0.65,"Vehicle-Heavy","Mixed")))) -> Infantry-Heavy
A6: =Player_Class_Profile!A6 -> TheBishopDeath | B6: 47 | C6: 544 | D6: 5.5 | E6: 83 | F6: 0.75 | G6: 13 | H6: 9 | I6: 4.5 | J6: 3 | K6: 4.75 | L6: 6.5 | M6: 1.25 | N6: 3 | O6: 0.75 | P6: =SUM(Player_Mode_Profile!C6:D6) -> 549.5 | Q6: =SUM(Player_Mode_Profile!E6:F6) -> 83.75 | R6: =SUM(Player_Mode_Profile!G6:M6) -> 42 | S6: =SUM(Player_Mode_Profile!N6:O6) -> 3.75 | T6: =SUM(P6:S6) -> 679 | U6: =IF(SUM(P6:S6)=0,"",IF(S6/SUM(P6:S6)>=0.5,"Battle Royale",IF(R6/SUM(P6:R6)>=0.6,"Infantry-Heavy",IF((P6+0.7*Q6)/SUM(P6:R6)>=0.65,"Vehicle-Heavy","Mixed")))) -> Vehicle-Heavy
A7: =Player_Class_Profile!A7 -> AncientWizardGuy | B7: 57 | C7: 234 | D7: 242 | E7: 237 | F7: 13 | G7: 0 | H7: 0 | I7: 0 | J7: 0 | K7: 1.25 | L7: 0.75 | M7: 0 | N7: 0 | O7: 0 | P7: =SUM(Player_Mode_Profile!C7:D7) -> 476 | Q7: =SUM(Player_Mode_Profile!E7:F7) -> 250 | R7: =SUM(Player_Mode_Profile!G7:M7) -> 2 | S7: =SUM(Player_Mode_Profile!N7:O7) -> 0 | T7: =SUM(P7:S7) -> 728 | U7: =IF(SUM(P7:S7)=0,"",IF(S7/SUM(P7:S7)>=0.5,"Battle Royale",IF(R7/SUM(P7:R7)>=0.6,"Infantry-Heavy",IF((P7+0.7*Q7)/SUM(P7:R7)>=0.65,"Vehicle-Heavy","Mixed")))) -> Vehicle-Heavy
A8: =Player_Class_Profile!A8 -> M5_eaglez | B8: 67 | C8: 177 | D8: 37 | E8: 453 | F8: 0.5 | G8: 0 | H8: 0 | I8: 0 | J8: 0 | K8: 0 | L8: 0.25 | M8: 0 | N8: 0 | O8: 0 | P8: =SUM(Player_Mode_Profile!C8:D8) -> 214 | Q8: =SUM(Player_Mode_Profile!E8:F8) -> 453.5 | R8: =SUM(Player_Mode_Profile!G8:M8) -> 0.25 | S8: =SUM(Player_Mode_Profile!N8:O8) -> 0 | T8: =SUM(P8:S8) -> 667.75 | U8: =IF(SUM(P8:S8)=0,"",IF(S8/SUM(P8:S8)>=0.5,"Battle Royale",IF(R8/SUM(P8:R8)>=0.6,"Infantry-Heavy",IF((P8+0.7*Q8)/SUM(P8:R8)>=0.65,"Vehicle-Heavy","Mixed")))) -> Vehicle-Heavy
A9: =Player_Class_Profile!A9 -> Ragefast2311 | B9: 77 | C9: 29 | D9: 14 | E9: 45 | F9: 4.5 | G9: 139 | H9: 52 | I9: 4 | J9: 27 | K9: 135 | L9: 4.25 | M9: 2.5 | N9: 4.25 | O9: 11 | P9: =SUM(Player_Mode_Profile!C9:D9) -> 43 | Q9: =SUM(Player_Mode_Profile!E9:F9) -> 49.5 | R9: =SUM(Player_Mode_Profile!G9:M9) -> 363.75 | S9: =SUM(Player_Mode_Profile!N9:O9) -> 15.25 | T9: =SUM(P9:S9) -> 471.5 | U9: =IF(SUM(P9:S9)=0,"",IF(S9/SUM(P9:S9)>=0.5,"Battle Royale",IF(R9/SUM(P9:R9)>=0.6,"Infantry-Heavy",IF((P9+0.7*Q9)/SUM(P9:R9)>=0.65,"Vehicle-Heavy","Mixed")))) -> Infantry-Heavy
A10: =Player_Class_Profile!A10 -> xCPC464x | B10: 87 | C10: 315 | D10: 157 | E10: 135 | F10: 36 | G10: 8.25 | H10: 5.75 | I10: 6.25 | J10: 167 | K10: 9 | L10: 9.25 | M10: 11.5 | N10: 61 | O10: 67 | P10: =SUM(Player_Mode_Profile!C10:D10) -> 472 | Q10: =SUM(Player_Mode_Profile!E10:F10) -> 171 | R10: =SUM(Player_Mode_Profile!G10:M10) -> 217 | S10: =SUM(Player_Mode_Profile!N10:O10) -> 128 | T10: =SUM(P10:S10) -> 988 | U10: =IF(SUM(P10:S10)=0,"",IF(S10/SUM(P10:S10)>=0.5,"Battle Royale",IF(R10/SUM(P10:R10)>=0.6,"Infantry-Heavy",IF((P10+0.7*Q10)/SUM(P10:R10)>=0.65,"Vehicle-Heavy","Mixed")))) -> Vehicle-Heavy
A11: =Player_Class_Profile!A11 -> Benzo_ | B11: 97 | C11: 45 | D11: 33 | E11: 634 | F11: 1.25 | G11: 1.75 | H11: 0 | I11: 0 | J11: 5 | K11: 3 | L11: 1.75 | M11: 0 | N11: 8.25 | O11: 12 | P11: =SUM(Player_Mode_Profile!C11:D11) -> 78 | Q11: =SUM(Player_Mode_Profile!E11:F11) -> 635.25 | R11: =SUM(Player_Mode_Profile!G11:M11) -> 11.5 | S11: =SUM(Player_Mode_Profile!N11:O11) -> 20.25 | T11: =SUM(P11:S11) -> 745 | U11: =IF(SUM(P11:S11)=0,"",IF(S11/SUM(P11:S11)>=0.5,"Battle Royale",IF(R11/SUM(P11:R11)>=0.6,"Infantry-Heavy",IF((P11+0.7*Q11)/SUM(P11:R11)>=0.65,"Vehicle-Heavy","Mixed")))) -> Vehicle-Heavy
A12: =Player_Class_Profile!A12 -> rgayregger | B12: 107 | C12: 80 | D12: 42 | E12: 138 | F12: 25 | G12: 4 | H12: 2 | I12: 2.5 | J12: 0 | K12: 55 | L12: 54 | M12: 6 | N12: 0.75 | O12: 0.25 | P12: =SUM(Player_Mode_Profile!C12:D12) -> 122 | Q12: =SUM(Player_Mode_Profile!E12:F12) -> 163 | R12: =SUM(Player_Mode_Profile!G12:M12) -> 123.5 | S12: =SUM(Player_Mode_Profile!N12:O12) -> 1 | T12: =SUM(P12:S12) -> 409.5 | U12: =IF(SUM(P12:S12)=0,"",IF(S12/SUM(P12:S12)>=0.5,"Battle Royale",IF(R12/SUM(P12:R12)>=0.6,"Infantry-Heavy",IF((P12+0.7*Q12)/SUM(P12:R12)>=0.65,"Vehicle-Heavy","Mixed")))) -> Mixed
A13: =Player_Class_Profile!A13 -> dark_ken2284 | B13: 117 | C13: 7 | D13: 0 | E13: 102 | F13: 1 | G13: 6.75 | H13: 1.75 | I13: 0 | J13: 0.25 | K13: 149 | L13: 150 | M13: 2.75 | N13: 2.75 | O13: 85 | P13: =SUM(Player_Mode_Profile!C13:D13) -> 7 | Q13: =SUM(Player_Mode_Profile!E13:F13) -> 103 | R13: =SUM(Player_Mode_Profile!G13:M13) -> 310.5 | S13: =SUM(Player_Mode_Profile!N13:O13) -> 87.75 | T13: =SUM(P13:S13) -> 508.25 | U13: =IF(SUM(P13:S13)=0,"",IF(S13/SUM(P13:S13)>=0.5,"Battle Royale",IF(R13/SUM(P13:R13)>=0.6,"Infantry-Heavy",IF((P13+0.7*Q13)/SUM(P13:R13)>=0.7,"Vehicle-Heavy","Mixed")))) -> Infantry-Heavy
A14: =Player_Class_Profile!A14 -> Mosthated220 | B14: 127 | C14: 0.25 | D14: 0.5 | E14: 3 | F14: 0 | G14: 352 | H14: 9.5 | I14: 3.5 | J14: 3 | K14: 1 | L14: 0 | M14: 0.5 | N14: 1 | O14: 1.25 | P14: =SUM(Player_Mode_Profile!C14:D14) -> 0.75 | Q14: =SUM(Player_Mode_Profile!E14:F14) -> 3 | R14: =SUM(Player_Mode_Profile!G14:M14) -> 369.5 | S14: =SUM(Player_Mode_Profile!N14:O14) -> 2.25 | T14: =SUM(P14:S14) -> 375.5 | U14: =IF(SUM(P14:S14)=0,"",IF(S14/SUM(P14:S14)>=0.5,"Battle Royale",IF(R14/SUM(P14:R14)>=0.6,"Infantry-Heavy",IF((P14+0.7*Q14)/SUM(P14:R14)>=0.7,"Vehicle-Heavy","Mixed")))) -> Infantry-Heavy
A15: =Player_Class_Profile!A15 -> Bilbo-Fragginz88 | B15: 137 | C15: 10.5 | D15: 0.5 | E15: 9 | F15: 0.5 | G15: 141 | H15: 66 | I15: 0 | J15: 5.5 | K15: 53 | L15: 60 | M15: 1 | N15: 0 | O15: 0 | P15: =SUM(Player_Mode_Profile!C15:D15) -> 11 | Q15: =SUM(Player_Mode_Profile!E15:F15) -> 9.5 | R15: =SUM(Player_Mode_Profile!G15:M15) -> 326.5 | S15: =SUM(Player_Mode_Profile!N15:O15) -> 0 | T15: =SUM(P15:S15) -> 347 | U15: =IF(SUM(P15:S15)=0,"",IF(S15/SUM(P15:S15)>=0.5,"Battle Royale",IF(R15/SUM(P15:R15)>=0.6,"Infantry-Heavy",IF((P15+0.7*Q15)/SUM(P15:R15)>=0.7,"Vehicle-Heavy","Mixed")))) -> Infantry-Heavy
A16: =Player_Class_Profile!A16 -> xensis | B16: 147 | C16: 771 | D16: 90 | E16: 30 | F16: 4 | G16: 1.25 | H16: 0.5 | I16: 0.5 | J16: 2.5 | K16: 3 | L16: 1.25 | M16: 1 | N16: 1.25 | O16: 0 | P16: =SUM(Player_Mode_Profile!C16:D16) -> 861 | Q16: =SUM(Player_Mode_Profile!E16:F16) -> 34 | R16: =SUM(Player_Mode_Profile!G16:M16) -> 10 | S16: =SUM(Player_Mode_Profile!N16:O16) -> 1.25 | T16: =SUM(P16:S16) -> 906.25 | U16: =IF(SUM(P16:S16)=0,"",IF(S16/SUM(P16:S16)>=0.5,"Battle Royale",IF(R16/SUM(P16:R16)>=0.6,"Infantry-Heavy",IF((P16+0.7*Q16)/SUM(P16:R16)>=0.7,"Vehicle-Heavy","Mixed")))) -> Vehicle-Heavy
A17: =Player_Class_Profile!A17 -> Hogwarts | B17: 157 | C17: 204 | D17: 202 | E17: 49 | F17: 14 | G17: 2.75 | H17: 3 | I17: 0.5 | J17: 24 | K17: 3.25 | L17: 3.25 | M17: 9 | N17: 5 | O17: 16 | P17: =SUM(Player_Mode_Profile!C17:D17) -> 406 | Q17: =SUM(Player_Mode_Profile!E17:F17) -> 63 | R17: =SUM(Player_Mode_Profile!G17:M17) -> 45.75 | S17: =SUM(Player_Mode_Profile!N17:O17) -> 21 | T17: =SUM(P17:S17) -> 535.75 | U17: =IF(SUM(P17:S17)=0,"",IF(S17/SUM(P17:S17)>=0.5,"Battle Royale",IF(R17/SUM(P17:R17)>=0.6,"Infantry-Heavy",IF((P17+0.7*Q17)/SUM(P17:R17)>=0.7,"Vehicle-Heavy","Mixed")))) -> Vehicle-Heavy
A18: =Player_Class_Profile!A18 -> Vince77820 | B18: 167 | C18: 344 | D18: 206 | E18: 62 | F18: 31 | G18: 6.75 | H18: 12 | I18: 2.5 | J18: 0 | K18: 10.75 | L18: 14 | M18: 2 | N18: 0.25 | O18: 4.25 | P18: =SUM(Player_Mode_Profile!C18:D18) -> 550 | Q18: =SUM(Player_Mode_Profile!E18:F18) -> 93 | R18: =SUM(Player_Mode_Profile!G18:M18) -> 48 | S18: =SUM(Player_Mode_Profile!N18:O18) -> 4.5 | T18: =SUM(P18:S18) -> 695.5 | U18: =IF(SUM(P18:S18)=0,"",IF(S18/SUM(P18:S18)>=0.5,"Battle Royale",IF(R18/SUM(P18:R18)>=0.6,"Infantry-Heavy",IF((P18+0.7*Q18)/SUM(P18:R18)>=0.7,"Vehicle-Heavy","Mixed")))) -> Vehicle-Heavy
A19: =Player_Class_Profile!A19 -> issa_coot | B19: 177 | C19: 313 | D19: 128 | E19: 104 | F19: 12 | G19: 4.25 | H19: 7.75 | I19: 1.5 | J19: 8.75 | K19: 5.25 | L19: 7.25 | M19: 10.5 | N19: 4.25 | O19: 0 | P19: =SUM(Player_Mode_Profile!C19:D19) -> 441 | Q19: =SUM(Player_Mode_Profile!E19:F19) -> 116 | R19: =SUM(Player_Mode_Profile!G19:M19) -> 45.25 | S19: =SUM(Player_Mode_Profile!N19:O19) -> 4.25 | T19: =SUM(P19:S19) -> 606.5 | U19: =IF(SUM(P19:S19)=0,"",IF(S19/SUM(P19:S19)>=0.5,"Battle Royale",IF(R19/SUM(P19:R19)>=0.6,"Infantry-Heavy",IF((P19+0.7*Q19)/SUM(P19:R19)>=0.7,"Vehicle-Heavy","Mixed")))) -> Vehicle-Heavy
A20: =Player_Class_Profile!A20 -> Altelete | B20: 187 | C20: 653 | D20: 208 | E20: 125 | F20: 3.25 | G20: 0.75 | H20: 0 | I20: 0.75 | J20: 13 | K20: 5.5 | L20: 1.25 | M20: 1 | N20: 36 | O20: 0 | P20: =SUM(Player_Mode_Profile!C20:D20) -> 861 | Q20: =SUM(Player_Mode_Profile!E20:F20) -> 128.25 | R20: =SUM(Player_Mode_Profile!G20:M20) -> 22.25 | S20: =SUM(Player_Mode_Profile!N20:O20) -> 36 | T20: =SUM(P20:S20) -> 1047.5 | U20: =IF(SUM(P20:S20)=0,"",IF(S20/SUM(P20:S20)>=0.5,"Battle Royale",IF(R20/SUM(P20:R20)>=0.6,"Infantry-Heavy",IF((P20+0.7*Q20)/SUM(P20:R20)>=0.7,"Vehicle-Heavy","Mixed")))) -> Vehicle-Heavy
A21: =Player_Class_Profile!A21 -> on3fr3ak | B21: 197 | C21: 565 | D21: 20 | E21: 15 | F21: 10.25 | G21: 3 | H21: 2 | I21: 2 | J21: 12 | K21: 4.75 | L21: 6.75 | M21: 7 | N21: 3 | O21: 14 | P21: =SUM(Player_Mode_Profile!C21:D21) -> 585 | Q21: =SUM(Player_Mode_Profile!E21:F21) -> 25.25 | R21: =SUM(Player_Mode_Profile!G21:M21) -> 37.5 | S21: =SUM(Player_Mode_Profile!N21:O21) -> 17 | T21: =SUM(P21:S21) -> 664.75 | U21: =IF(SUM(P21:S21)=0,"",IF(S21/SUM(P21:S21)>=0.5,"Battle Royale",IF(R21/SUM(P21:R21)>=0.6,"Infantry-Heavy",IF((P21+0.7*Q21)/SUM(P21:R21)>=0.7,"Vehicle-Heavy","Mixed")))) -> Vehicle-Heavy
A22: =Player_Class_Profile!A22 -> Felliandro | B22: 207 | C22: 66 | D22: 12 | E22: 38 | F22: 41 | G22: 172 | H22: 52 | I22: 7.25 | J22: 11 | K22: 17 | L22: 6 | M22: 1 | N22: 8.5 | O22: 2 | P22: =SUM(Player_Mode_Profile!C22:D22) -> 78 | Q22: =SUM(Player_Mode_Profile!E22:F22) -> 79 | R22: =SUM(Player_Mode_Profile!G22:M22) -> 266.25 | S22: =SUM(Player_Mode_Profile!N22:O22) -> 10.5 | T22: =SUM(P22:S22) -> 433.75 | U22: =IF(SUM(P22:S22)=0,"",IF(S22/SUM(P22:S22)>=0.5,"Battle Royale",IF(R22/SUM(P22:R22)>=0.6,"Infantry-Heavy",IF((P22+0.7*Q22)/SUM(P22:R22)>=0.7,"Vehicle-Heavy","Mixed")))) -> Infantry-Heavy
A23: =Player_Class_Profile!A23 -> Tohu-1021 | B23: 217 | C23: 361 | D23: 29 | E23: 115 | F23: 60 | G23: 18 | H23: 6.25 | I23: 0 | J23: 13 | K23: 10.5 | L23: 13 | M23: 2 | N23: 8 | O23: 10.5 | P23: =SUM(Player_Mode_Profile!C23:D23) -> 390 | Q23: =SUM(Player_Mode_Profile!E23:F23) -> 175 | R23: =SUM(Player_Mode_Profile!G23:M23) -> 62.75 | S23: =SUM(Player_Mode_Profile!N23:O23) -> 18.5 | T23: =SUM(P23:S23) -> 646.25 | U23: =IF(SUM(P23:S23)=0,"",IF(S23/SUM(P23:S23)>=0.5,"Battle Royale",IF(R23/SUM(P23:R23)>=0.6,"Infantry-Heavy",IF((P23+0.7*Q23)/SUM(P23:R23)>=0.7,"Vehicle-Heavy","Mixed")))) -> Vehicle-Heavy
A24: =Player_Class_Profile!A24 -> Francko Escobar | B24: 227 | C24: 159 | D24: 19 | E24: 85 | F24: 19 | G24: 41 | H24: 11.5 | I24: 18 | J24: 64 | K24: 246 | L24: 41 | M24: 1.5 | N24: 6 | O24: 0.5 | P24: =SUM(Player_Mode_Profile!C24:D24) -> 178 | Q24: =SUM(Player_Mode_Profile!E24:F24) -> 104 | R24: =SUM(Player_Mode_Profile!G24:M24) -> 423 | S24: =SUM(Player_Mode_Profile!N24:O24) -> 6.5 | T24: =SUM(P24:S24) -> 711.5 | U24: =IF(SUM(P24:S24)=0,"",IF(S24/SUM(P24:S24)>=0.5,"Battle Royale",IF(R24/SUM(P24:R24)>=0.6,"Infantry-Heavy",IF((P24+0.7*Q24)/SUM(P24:R24)>=0.7,"Vehicle-Heavy","Mixed")))) -> Infantry-Heavy
... A101: =Player_Class_Profile!A101 -> tc_likeman01 | B101: 997 | C101: 283 | D101: 69 | E101: 150 | F101: 52 | G101: 30 | H101: 10.5 | I101: 6.5 | J101: 9.25 | K101: 16 | L101: 14 | M101: 4.25 | N101: 17 | O101: 4.25 | P101: =SUM(Player_Mode_Profile!C101:D101) -> 352 | Q101: =SUM(Player_Mode_Profile!E101:F101) -> 202 | R101: =SUM(Player_Mode_Profile!G101:M101) -> 90.5 | S101: =SUM(Player_Mode_Profile!N101:O101) -> 21.25 | T101: =SUM(P101:S101) -> 665.75 | U101: =IF(SUM(P101:S101)=0,"",IF(S101/SUM(P101:S101)>=0.5,"Battle Royale",IF(R101/SUM(P101:R101)>=0.6,"Infantry-Heavy",IF((P101+0.7*Q101)/SUM(P101:R101)>=0.7,"Vehicle-Heavy","Mixed")))) -> Vehicle-Heavy
B102: 1007 | U102: =IF(SUM(P102:S102)=0,"",IF(S102/SUM(P102:S102)>=0.5,"Battle Royale",IF(R102/SUM(P102:R102)>=0.6,"Infantry-Heavy",IF((P102+0.7*Q102)/SUM(P102:R102)>=0.7,"Vehicle-Heavy","Mixed"))))
B103: 1017 | U103: =IF(SUM(P103:S103)=0,"",IF(S103/SUM(P103:S103)>=0.5,"Battle Royale",IF(R103/SUM(P103:R103)>=0.6,"Infantry-Heavy",IF((P103+0.7*Q103)/SUM(P103:R103)>=0.7,"Vehicle-Heavy","Mixed"))))
B104: 1027 | U104: =IF(SUM(P104:S104)=0,"",IF(S104/SUM(P104:S104)>=0.5,"Battle Royale",IF(R104/SUM(P104:R104)>=0.6,"Infantry-Heavy",IF((P104+0.7*Q104)/SUM(P104:R104)>=0.7,"Vehicle-Heavy","Mixed"))))
B105: 1037 | U105: =IF(SUM(P105:S105)=0,"",IF(S105/SUM(P105:S105)>=0.5,"Battle Royale",IF(R105/SUM(P105:R105)>=0.6,"Infantry-Heavy",IF((P105+0.7*Q105)/SUM(P105:R105)>=0.7,"Vehicle-Heavy","Mixed"))))
B106: 1047 | U106: =IF(SUM(P106:S106)=0,"",IF(S106/SUM(P106:S106)>=0.5,"Battle Royale",IF(R106/SUM(P106:R106)>=0.6,"Infantry-Heavy",IF((P106+0.7*Q106)/SUM(P106:R106)>=0.7,"Vehicle-Heavy","Mixed"))))
B107: 1057 | U107: =IF(SUM(P107:S107)=0,"",IF(S107/SUM(P107:S107)>=0.5,"Battle Royale",IF(R107/SUM(P107:R107)>=0.6,"Infantry-Heavy",IF((P107+0.7*Q107)/SUM(P107:R107)>=0.7,"Vehicle-Heavy","Mixed"))))
B108: 1067 | U108: =IF(SUM(P108:S108)=0,"",IF(S108/SUM(P108:S108)>=0.5,"Battle Royale",IF(R108/SUM(P108:R108)>=0.6,"Infantry-Heavy",IF((P108+0.7*Q108)/SUM(P108:R108)>=0.7,"Vehicle-Heavy","Mixed"))))
B109: 1077 | U109: =IF(SUM(P109:S109)=0,"",IF(S109/SUM(P109:S109)>=0.5,"Battle Royale",IF(R109/SUM(P109:R109)>=0.6,"Infantry-Heavy",IF((P109+0.7*Q109)/SUM(P109:R109)>=0.7,"Vehicle-Heavy","Mixed"))))
B110: 1087 | U110: =IF(SUM(P110:S110)=0,"",IF(S110/SUM(P110:S110)>=0.5,"Battle Royale",IF(R110/SUM(P110:R110)>=0.6,"Infantry-Heavy",IF((P110+0.7*Q110)/SUM(P110:R110)>=0.7,"Vehicle-Heavy","Mixed"))))
B111: 1097 | U111: =IF(SUM(P111:S111)=0,"",IF(S111/SUM(P111:S111)>=0.5,"Battle Royale",IF(R111/SUM(P111:R111)>=0.6,"Infantry-Heavy",IF((P111+0.7*Q111)/SUM(P111:R111)>=0.7,"Vehicle-Heavy","Mixed"))))
B112: 1107 | U112: =IF(SUM(P112:S112)=0,"",IF(S112/SUM(P112:S112)>=0.5,"Battle Royale",IF(R112/SUM(P112:R112)>=0.6,"Infantry-Heavy",IF((P112+0.7*Q112)/SUM(P112:R112)>=0.7,"Vehicle-Heavy","Mixed"))))
B113: 1117 | U113: =IF(SUM(P113:S113)=0,"",IF(S113/SUM(P113:S113)>=0.5,"Battle Royale",IF(R113/SUM(P113:R113)>=0.6,"Infantry-Heavy",IF((P113+0.7*Q113)/SUM(P113:R113)>=0.7,"Vehicle-Heavy","Mixed"))))
... B1000: 9987 | U1000: =IF(SUM(P1000:S1000)=0,"",IF(S1000/SUM(P1000:S1000)>=0.5,"Battle Royale",IF(R1000/SUM(P1000:R1000)>=0.6,"Infantry-Heavy",IF((P1000+0.7*Q1000)/SUM(P1000:R1000)>=0.7,"Vehicle-Heavy","Mixed"))))
B1001: 9997

Sheet Class_Mode_Bridge
A1: Player_ID | B1: Leaderboard_Rank | C1: Assault_Share | D1: Engineer_Share | E1: Recon_Share | F1: Support_Share | G1: Vehicle_Share | H1: Mixed_Share | I1: Infantry_Share | J1: BR_Share
A2: =Player_Mode_Profile!A2 -> Stann83cz | B2: {=_xlfn.SEQUENCE(1000,1,7,10)} -> 7 | C2: =Player_Class_Profile!D2/Player_Class_Profile!H2 -> 0.53016453 | D2: =Player_Class_Profile!E2/Player_Class_Profile!H2 -> 0.07678245 | E2: =Player_Class_Profile!F2/Player_Class_Profile!H2 -> 0.27422303 | F2: =Player_Class_Profile!G2/Player_Class_Profile!H2 -> 0.11882998 | G2: =(_xlfn.XLOOKUP($A2,Player_Mode_Profile!$A:$A,Player_Mode_Profile!P:P)/(_xlfn.XLOOKUP($A2,Player_Mode_Profile!$A:$A,Player_Mode_Profile!$T:$T))) -> 0.33633634 | H2: =(_xlfn.XLOOKUP($A2,Player_Mode_Profile!$A:$A,Player_Mode_Profile!Q:Q)/(_xlfn.XLOOKUP($A2,Player_Mode_Profile!$A:$A,Player_Mode_Profile!$T:$T))) -> 0.15840841 | I2: =(_xlfn.XLOOKUP($A2,Player_Mode_Profile!$A:$A,Player_Mode_Profile!R:R)/(_xlfn.XLOOKUP($A2,Player_Mode_Profile!$A:$A,Player_Mode_Profile!$T:$T))) -> 0.48873874 | J2: =(_xlfn.XLOOKUP($A2,Player_Mode_Profile!$A:$A,Player_Mode_Profile!S:S)/(_xlfn.XLOOKUP($A2,Player_Mode_Profile!$A:$A,Player_Mode_Profile!$T:$T))) -> 0.016516517
A3: =Player_Mode_Profile!A3 -> Sir Jekyll | B3: 17 | C3: =Player_Class_Profile!D3/Player_Class_Profile!H3 -> 0.29931973 | D3: =Player_Class_Profile!E3/Player_Class_Profile!H3 -> 0.36734694 | E3: =Player_Class_Profile!F3/Player_Class_Profile!H3 -> 0.1122449 | F3: =Player_Class_Profile!G3/Player_Class_Profile!H3 -> 0.22108844 | G3: =(_xlfn.XLOOKUP($A3,Player_Mode_Profile!$A:$A,Player_Mode_Profile!P:P)/(_xlfn.XLOOKUP($A3,Player_Mode_Profile!$A:$A,Player_Mode_Profile!$T:$T))) -> 0.51248164 | H3: =(_xlfn.XLOOKUP($A3,Player_Mode_Profile!$A:$A,Player_Mode_Profile!Q:Q)/(_xlfn.XLOOKUP($A3,Player_Mode_Profile!$A:$A,Player_Mode_Profile!$T:$T))) -> 0.15638767 | I3: =(_xlfn.XLOOKUP($A3,Player_Mode_Profile!$A:$A,Player_Mode_Profile!R:R)/(_xlfn.XLOOKUP($A3,Player_Mode_Profile!$A:$A,Player_Mode_Profile!$T:$T))) -> 0.14904552 | J3: =(_xlfn.XLOOKUP($A3,Player_Mode_Profile!$A:$A,Player_Mode_Profile!S:S)/(_xlfn.XLOOKUP($A3,Player_Mode_Profile!$A:$A,Player_Mode_Profile!$T:$T))) -> 0.18208517
A4: =Player_Mode_Profile!A4 -> elkikisk | B4: 27 | C4: =Player_Class_Profile!D4/Player_Class_Profile!H4 -> 0.41475827 | D4: =Player_Class_Profile!E4/Player_Class_Profile!H4 -> 0.24936387 | E4: =Player_Class_Profile!F4/Player_Class_Profile!H4 -> 0.05216285 | F4: =Player_Class_Profile!G4/Player_Class_Profile!H4 -> 0.28371501 | G4: =(_xlfn.XLOOKUP($A4,Player_Mode_Profile!$A:$A,Player_Mode_Profile!P:P)/(_xlfn.XLOOKUP($A4,Player_Mode_Profile!$A:$A,Player_Mode_Profile!$T:$T))) -> 0.85453673 | H4: =(_xlfn.XLOOKUP($A4,Player_Mode_Profile!$A:$A,Player_Mode_Profile!Q:Q)/(_xlfn.XLOOKUP($A4,Player_Mode_Profile!$A:$A,Player_Mode_Profile!$T:$T))) -> 0.13015416 | I4: =(_xlfn.XLOOKUP($A4,Player_Mode_Profile!$A:$A,Player_Mode_Profile!R:R)/(_xlfn.XLOOKUP($A4,Player_Mode_Profile!$A:$A,Player_Mode_Profile!$T:$T))) -> 0.014935723 | J4: =(_xlfn.XLOOKUP($A4,Player_Mode_Profile!$A:$A,Player_Mode_Profile!S:S)/(_xlfn.XLOOKUP($A4,Player_Mode_Profile!$A:$A,Player_Mode_Profile!$T:$T))) -> 0.00037339308
A5: =Player_Mode_Profile!A5 -> HSBxEWIKKED | B5: 37 | C5: =Player_Class_Profile!D5/Player_Class_Profile!H5 -> 0.0012738854 | D5: =Player_Class_Profile!E5/Player_Class_Profile!H5 -> 0.010191083 | E5: =Player_Class_Profile!F5/Player_Class_Profile!H5 -> 0.13375796 | F5: =Player_Class_Profile!G5/Player_Class_Profile!H5 -> 0.85477707 | G5: =(_xlfn.XLOOKUP($A5,Player_Mode_Profile!$A:$A,Player_Mode_Profile!P:P)/(_xlfn.XLOOKUP($A5,Player_Mode_Profile!$A:$A,Player_Mode_Profile!$T:$T))) -> 0.11025571 | H5: =(_xlfn.XLOOKUP($A5,Player_Mode_Profile!$A:$A,Player_Mode_Profile!Q:Q)/(_xlfn.XLOOKUP($A5,Player_Mode_Profile!$A:$A,Player_Mode_Profile!$T:$T))) -> 0.1022821 | I5: =(_xlfn.XLOOKUP($A5,Player_Mode_Profile!$A:$A,Player_Mode_Profile!R:R)/(_xlfn.XLOOKUP($A5,Player_Mode_Profile!$A:$A,Player_Mode_Profile!$T:$T))) -> 0.66098433 | J5: =(_xlfn.XLOOKUP($A5,Player_Mode_Profile!$A:$A,Player_Mode_Profile!S:S)/(_xlfn.XLOOKUP($A5,Player_Mode_Profile!$A:$A,Player_Mode_Profile!$T:$T))) -> 0.12647787
A6: =Player_Mode_Profile!A6 -> TheBishopDeath | B6: 47 | C6: =Player_Class_Profile!D6/Player_Class_Profile!H6 -> 0.19626168 | D6: =Player_Class_Profile!E6/Player_Class_Profile!H6 -> 0.72897196 | E6: =Player_Class_Profile!F6/Player_Class_Profile!H6 -> 0.0056074766 | F6: =Player_Class_Profile!G6/Player_Class_Profile!H6 -> 0.069158879 | G6: =(_xlfn.XLOOKUP($A6,Player_Mode_Profile!$A:$A,Player_Mode_Profile!P:P)/(_xlfn.XLOOKUP($A6,Player_Mode_Profile!$A:$A,Player_Mode_Profile!$T:$T))) -> 0.80927835 | H6: =(_xlfn.XLOOKUP($A6,Player_Mode_Profile!$A:$A,Player_Mode_Profile!Q:Q)/(_xlfn.XLOOKUP($A6,Player_Mode_Profile!$A:$A,Player_Mode_Profile!$T:$T))) -> 0.12334315 | I6: =(_xlfn.XLOOKUP($A6,Player_Mode_Profile!$A:$A,Player_Mode_Profile!R:R)/(_xlfn.XLOOKUP($A6,Player_Mode_Profile!$A:$A,Player_Mode_Profile!$T:$T))) -> 0.06185567 | J6: =(_xlfn.XLOOKUP($A6,Player_Mode_Profile!$A:$A,Player_Mode_Profile!S:S)/(_xlfn.XLOOKUP($A6,Player_Mode_Profile!$A:$A,Player_Mode_Profile!$T:$T))) -> 0.0055228277
A7: =Player_Mode_Profile!A7 -> AncientWizardGuy | B7: 57 | C7: =Player_Class_Profile!D7/Player_Class_Profile!H7 -> 0.17420436 | D7: =Player_Class_Profile!E7/Player_Class_Profile!H7 -> 0.26130653 | E7: =Player_Class_Profile!F7/Player_Class_Profile!H7 -> 0.21105528 | F7: =Player_Class_Profile!G7/Player_Class_Profile!H7 -> 0.35343384 | G7: =(_xlfn.XLOOKUP($A7,Player_Mode_Profile!$A:$A,Player_Mode_Profile!P:P)/(_xlfn.XLOOKUP($A7,Player_Mode_Profile!$A:$A,Player_Mode_Profile!$T:$T))) -> 0.65384615 | H7: =(_xlfn.XLOOKUP($A7,Player_Mode_Profile!$A:$A,Player_Mode_Profile!Q:Q)/(_xlfn.XLOOKUP($A7,Player_Mode_Profile!$A:$A,Player_Mode_Profile!$T:$T))) -> 0.34340659 | I7: =(_xlfn.XLOOKUP($A7,Player_Mode_Profile!$A:$A,Player_Mode_Profile!R:R)/(_xlfn.XLOOKUP($A7,Player_Mode_Profile!$A:$A,Player_Mode_Profile!$T:$T))) -> 0.0027472527 | J7: =(_xlfn.XLOOKUP($A7,Player_Mode_Profile!$A:$A,Player_Mode_Profile!S:S)/(_xlfn.XLOOKUP($A7,Player_Mode_Profile!$A:$A,Player_Mode_Profile!$T:$T))) -> 0
A8: =Player_Mode_Profile!A8 -> M5_eaglez | B8: 67 | C8: =Player_Class_Profile!D8/Player_Class_Profile!H8 -> 0.52008929 | D8: =Player_Class_Profile!E8/Player_Class_Profile!H8 -> 0.15178571 | E8: =Player_Class_Profile!F8/Player_Class_Profile!H8 -> 0.13839286 | F8: =Player_Class_Profile!G8/Player_Class_Profile!H8 -> 0.18973214 | G8: =(_xlfn.XLOOKUP($A8,Player_Mode_Profile!$A:$A,Player_Mode_Profile!P:P)/(_xlfn.XLOOKUP($A8,Player_Mode_Profile!$A:$A,Player_Mode_Profile!$T:$T))) -> 0.32047922 | H8: =(_xlfn.XLOOKUP($A8,Player_Mode_Profile!$A:$A,Player_Mode_Profile!Q:Q)/(_xlfn.XLOOKUP($A8,Player_Mode_Profile!$A:$A,Player_Mode_Profile!$T:$T))) -> 0.67914639 | I8: =(_xlfn.XLOOKUP($A8,Player_Mode_Profile!$A:$A,Player_Mode_Profile!R:R)/(_xlfn.XLOOKUP($A8,Player_Mode_Profile!$A:$A,Player_Mode_Profile!$T:$T))) -> 0.00037439161 | J8: =(_xlfn.XLOOKUP($A8,Player_Mode_Profile!$A:$A,Player_Mode_Profile!S:S)/(_xlfn.XLOOKUP($A8,Player_Mode_Profile!$A:$A,Player_Mode_Profile!$T:$T))) -> 0
A9: =Player_Mode_Profile!A9 -> Ragefast2311 | B9: 77 | C9: =Player_Class_Profile!D9/Player_Class_Profile!H9 -> 0.022727273 | D9: =Player_Class_Profile!E9/Player_Class_Profile!H9 -> 0.020454545 | E9: =Player_Class_Profile!F9/Player_Class_Profile!H9 -> 0.027272727 | F9: =Player_Class_Profile!G9/Player_Class_Profile!H9 -> 0.92954545 | G9: =(_xlfn.XLOOKUP($A9,Player_Mode_Profile!$A:$A,Player_Mode_Profile!P:P)/(_xlfn.XLOOKUP($A9,Player_Mode_Profile!$A:$A,Player_Mode_Profile!$T:$T))) -> 0.091198303 | H9: =(_xlfn.XLOOKUP($A9,Player_Mode_Profile!$A:$A,Player_Mode_Profile!Q:Q)/(_xlfn.XLOOKUP($A9,Player_Mode_Profile!$A:$A,Player_Mode_Profile!$T:$T))) -> 0.10498409 | I9: =(_xlfn.XLOOKUP($A9,Player_Mode_Profile!$A:$A,Player_Mode_Profile!R:R)/(_xlfn.XLOOKUP($A9,Player_Mode_Profile!$A:$A,Player_Mode_Profile!$T:$T))) -> 0.77147402 | J9: =(_xlfn.XLOOKUP($A9,Player_Mode_Profile!$A:$A,Player_Mode_Profile!S:S)/(_xlfn.XLOOKUP($A9,Player_Mode_Profile!$A:$A,Player_Mode_Profile!$T:$T))) -> 0.032343584
A10: =Player_Mode_Profile!A10 -> xCPC464x | B10: 87 | C10: =Player_Class_Profile!D10/Player_Class_Profile!H10 -> 0.54961832 | D10: =Player_Class_Profile!E10/Player_Class_Profile!H10 -> 0.053435115 | E10: =Player_Class_Profile!F10/Player_Class_Profile!H10 -> 0.31145038 | F10: =Player_Class_Profile!G10/Player_Class_Profile!H10 -> 0.085496183 | G10: =(_xlfn.XLOOKUP($A10,Player_Mode_Profile!$A:$A,Player_Mode_Profile!P:P)/(_xlfn.XLOOKUP($A10,Player_Mode_Profile!$A:$A,Player_Mode_Profile!$T:$T))) -> 0.47773279 | H10: =(_xlfn.XLOOKUP($A10,Player_Mode_Profile!$A:$A,Player_Mode_Profile!Q:Q)/(_xlfn.XLOOKUP($A10,Player_Mode_Profile!$A:$A,Player_Mode_Profile!$T:$T))) -> 0.17307692 | I10: =(_xlfn.XLOOKUP($A10,Player_Mode_Profile!$A:$A,Player_Mode_Profile!R:R)/(_xlfn.XLOOKUP($A10,Player_Mode_Profile!$A:$A,Player_Mode_Profile!$T:$T))) -> 0.21963563 | J10: =(_xlfn.XLOOKUP($A10,Player_Mode_Profile!$A:$A,Player_Mode_Profile!S:S)/(_xlfn.XLOOKUP($A10,Player_Mode_Profile!$A:$A,Player_Mode_Profile!$T:$T))) -> 0.12955466
A11: =Player_Mode_Profile!A11 -> Benzo_ | B11: 97 | C11: =Player_Class_Profile!D11/Player_Class_Profile!H11 -> 0.051724138 | D11: =Player_Class_Profile!E11/Player_Class_Profile!H11 -> 0.29118774 | E11: =Player_Class_Profile!F11/Player_Class_Profile!H11 -> 0.26819923 | F11: =Player_Class_Profile!G11/Player_Class_Profile!H11 -> 0.38888889 | G11: =(_xlfn.XLOOKUP($A11,Player_Mode_Profile!$A:$A,Player_Mode_Profile!P:P)/(_xlfn.XLOOKUP($A11,Player_Mode_Profile!$A:$A,Player_Mode_Profile!$T:$T))) -> 0.10469799 | H11: =(_xlfn.XLOOKUP($A11,Player_Mode_Profile!$A:$A,Player_Mode_Profile!Q:Q)/(_xlfn.XLOOKUP($A11,Player_Mode_Profile!$A:$A,Player_Mode_Profile!$T:$T))) -> 0.85268456 | I11: =(_xlfn.XLOOKUP($A11,Player_Mode_Profile!$A:$A,Player_Mode_Profile!R:R)/(_xlfn.XLOOKUP($A11,Player_Mode_Profile!$A:$A,Player_Mode_Profile!$T:$T))) -> 0.015436242 | J11: =(_xlfn.XLOOKUP($A11,Player_Mode_Profile!$A:$A,Player_Mode_Profile!S:S)/(_xlfn.XLOOKUP($A11,Player_Mode_Profile!$A:$A,Player_Mode_Profile!$T:$T))) -> 0.027181208
A12: =Player_Mode_Profile!A12 -> rgayregger | B12: 107 | C12: =Player_Class_Profile!D12/Player_Class_Profile!H12 -> 0.69421488 | D12: =Player_Class_Profile!E12/Player_Class_Profile!H12 -> 0.16253444 | E12: =Player_Class_Profile!F12/Player_Class_Profile!H12 -> 0.082644628 | F12: =Player_Class_Profile!G12/Player_Class_Profile!H12 -> 0.060606061 | G12: =(_xlfn.XLOOKUP($A12,Player_Mode_Profile!$A:$A,Player_Mode_Profile!P:P)/(_xlfn.XLOOKUP($A12,Player_Mode_Profile!$A:$A,Player_Mode_Profile!$T:$T))) -> 0.2979243 | H12: =(_xlfn.XLOOKUP($A12,Player_Mode_Profile!$A:$A,Player_Mode_Profile!Q:Q)/(_xlfn.XLOOKUP($A12,Player_Mode_Profile!$A:$A,Player_Mode_Profile!$T:$T))) -> 0.3980464 | I12: =(_xlfn.XLOOKUP($A12,Player_Mode_Profile!$A:$A,Player_Mode_Profile!R:R)/(_xlfn.XLOOKUP($A12,Player_Mode_Profile!$A:$A,Player_Mode_Profile!$T:$T))) -> 0.3015873 | J12: =(_xlfn.XLOOKUP($A12,Player_Mode_Profile!$A:$A,Player_Mode_Profile!S:S)/(_xlfn.XLOOKUP($A12,Player_Mode_Profile!$A:$A,Player_Mode_Profile!$T:$T))) -> 0.0024420024
A13: =Player_Mode_Profile!A13 -> dark_ken2284 | B13: 117 | C13: =Player_Class_Profile!D13/Player_Class_Profile!H13 -> 0.50214592 | D13: =Player_Class_Profile!E13/Player_Class_Profile!H13 -> 0.0064377682 | E13: =Player_Class_Profile!F13/Player_Class_Profile!H13 -> 0.22317597 | F13: =Player_Class_Profile!G13/Player_Class_Profile!H13 -> 0.26824034 | G13: =(_xlfn.XLOOKUP($A13,Player_Mode_Profile!$A:$A,Player_Mode_Profile!P:P)/(_xlfn.XLOOKUP($A13,Player_Mode_Profile!$A:$A,Player_Mode_Profile!$T:$T))) -> 0.01377275 | H13: =(_xlfn.XLOOKUP($A13,Player_Mode_Profile!$A:$A,Player_Mode_Profile!Q:Q)/(_xlfn.XLOOKUP($A13,Player_Mode_Profile!$A:$A,Player_Mode_Profile!$T:$T))) -> 0.20265617 | I13: =(_xlfn.XLOOKUP($A13,Player_Mode_Profile!$A:$A,Player_Mode_Profile!R:R)/(_xlfn.XLOOKUP($A13,Player_Mode_Profile!$A:$A,Player_Mode_Profile!$T:$T))) -> 0.61091982 | J13: =(_xlfn.XLOOKUP($A13,Player_Mode_Profile!$A:$A,Player_Mode_Profile!S:S)/(_xlfn.XLOOKUP($A13,Player_Mode_Profile!$A:$A,Player_Mode_Profile!$T:$T))) -> 0.17265125
A14: =Player_Mode_Profile!A14 -> Mosthated220 | B14: 127 | C14: =Player_Class_Profile!D14/Player_Class_Profile!H14 -> 0.30252101 | D14: =Player_Class_Profile!E14/Player_Class_Profile!H14 -> 0.24089636 | E14: =Player_Class_Profile!F14/Player_Class_Profile!H14 -> 0.25770308 | F14: =Player_Class_Profile!G14/Player_Class_Profile!H14 -> 0.19887955 | G14: =(_xlfn.XLOOKUP($A14,Player_Mode_Profile!$A:$A,Player_Mode_Profile!P:P)/(_xlfn.XLOOKUP($A14,Player_Mode_Profile!$A:$A,Player_Mode_Profile!$T:$T))) -> 0.0019973369 | H14: =(_xlfn.XLOOKUP($A14,Player_Mode_Profile!$A:$A,Player_Mode_Profile!Q:Q)/(_xlfn.XLOOKUP($A14,Player_Mode_Profile!$A:$A,Player_Mode_Profile!$T:$T))) -> 0.0079893475 | I14: =(_xlfn.XLOOKUP($A14,Player_Mode_Profile!$A:$A,Player_Mode_Profile!R:R)/(_xlfn.XLOOKUP($A14,Player_Mode_Profile!$A:$A,Player_Mode_Profile!$T:$T))) -> 0.9840213 | J14: =(_xlfn.XLOOKUP($A14,Player_Mode_Profile!$A:$A,Player_Mode_Profile!S:S)/(_xlfn.XLOOKUP($A14,Player_Mode_Profile!$A:$A,Player_Mode_Profile!$T:$T))) -> 0.0059920107
... A101: =Player_Mode_Profile!A101 -> tc_likeman01 | B101: 997 | C101: =Player_Class_Profile!D101/Player_Class_Profile!H101 -> 0.074398249 | D101: =Player_Class_Profile!E101/Player_Class_Profile!H101 -> 0.29321663 | E101: =Player_Class_Profile!F101/Player_Class_Profile!H101 -> 0.18161926 | F101: =Player_Class_Profile!G101/Player_Class_Profile!H101 -> 0.45076586 | G101: =(_xlfn.XLOOKUP($A101,Player_Mode_Profile!$A:$A,Player_Mode_Profile!P:P)/(_xlfn.XLOOKUP($A101,Player_Mode_Profile!$A:$A,Player_Mode_Profile!$T:$T))) -> 0.528727 | H101: =(_xlfn.XLOOKUP($A101,Player_Mode_Profile!$A:$A,Player_Mode_Profile!Q:Q)/(_xlfn.XLOOKUP($A101,Player_Mode_Profile!$A:$A,Player_Mode_Profile!$T:$T))) -> 0.3034172 | I101: =(_xlfn.XLOOKUP($A101,Player_Mode_Profile!$A:$A,Player_Mode_Profile!R:R)/(_xlfn.XLOOKUP($A101,Player_Mode_Profile!$A:$A,Player_Mode_Profile!$T:$T))) -> 0.13593691 | J101: =(_xlfn.XLOOKUP($A101,Player_Mode_Profile!$A:$A,Player_Mode_Profile!S:S)/(_xlfn.XLOOKUP($A101,Player_Mode_Profile!$A:$A,Player_Mode_Profile!$T:$T))) -> 0.031918888
B102: 1007
B103: 1017
B104: 1027
B105: 1037
B106: 1047
B107: 1057
B108: 1067
B109: 1077
B110: 1087
B111: 1097
B112: 1107
B113: 1117
... B1001: 9997

Sheet Correlation_Matrix
B1: Vehicle_Share | C1: Mixed_Share | D1: Infantry_Share | E1: BR_Share
A2: Assault_Share | B2: =CORREL(Class_Mode_Bridge!$C$2:$C$251, Class_Mode_Bridge!$G$2:$G$251) -> -0.10922779 | C2: =CORREL(Class_Mode_Bridge!$C$2:$C$251, Class_Mode_Bridge!$H$2:$H$251) -> 0.07802278 | D2: =CORREL(Class_Mode_Bridge!$C$2:$C$251, Class_Mode_Bridge!$I$2:$I$251) -> 0.095195544 | E2: =CORREL(Class_Mode_Bridge!$C$2:$C$251, Class_Mode_Bridge!$J$2:$J$251) -> -0.097035836
A3: Engineer_Share | B3: =CORREL(Class_Mode_Bridge!$D$2:$D$251, Class_Mode_Bridge!$G$2:$G$251) -> 0.29016327 | C3: =CORREL(Class_Mode_Bridge!$D$2:$D$251, Class_Mode_Bridge!$H$2:$H$251) -> -0.14510813 | D3: =CORREL(Class_Mode_Bridge!$D$2:$D$251, Class_Mode_Bridge!$I$2:$I$251) -> -0.22629216 | E3: =CORREL(Class_Mode_Bridge!$D$2:$D$251, Class_Mode_Bridge!$J$2:$J$251) -> 0.0067493613
A4: Recon_Share | B4: =CORREL(Class_Mode_Bridge!$E$2:$E$251, Class_Mode_Bridge!$G$2:$G$251) -> 0.013698772 | C4: =CORREL(Class_Mode_Bridge!$E$2:$E$251, Class_Mode_Bridge!$H$2:$H$251) -> 0.069896673 | D4: =CORREL(Class_Mode_Bridge!$E$2:$E$251, Class_Mode_Bridge!$I$2:$I$251) -> -0.1263667 | E4: =CORREL(Class_Mode_Bridge!$E$2:$E$251, Class_Mode_Bridge!$J$2:$J$251) -> 0.1194942
A5: Support_Share | B5: =CORREL(Class_Mode_Bridge!$F$2:$F$251, Class_Mode_Bridge!$G$2:$G$251) -> -0.16446002 | C5: =CORREL(Class_Mode_Bridge!$F$2:$F$251, Class_Mode_Bridge!$H$2:$H$251) -> -0.0021352294 | D5: =CORREL(Class_Mode_Bridge!$F$2:$F$251, Class_Mode_Bridge!$I$2:$I$251) -> 0.21651133 | E5: =CORREL(Class_Mode_Bridge!$F$2:$F$251, Class_Mode_Bridge!$J$2:$J$251) -> -0.02235572
